<robot name="creature">
	<link name="0">
		<visual>
			<geometry>
				<cylinder length="0.6412300284925913" radius="0.9455227376607734"/>
			</geometry>
		</visual>
		<collision>
			<geometry>
				<cylinder length="0.6412300284925913" radius="0.9455227376607734"/>
			</geometry>
		</collision>
		<inertial>
			<mass value="1.8009749775523782"/>
			<inertia ixx="0.03" iyy="0.03" izz="0.03" ixy="0" ixz="0" iyz="0"/>
		</inertial>
	</link>
	<link name="11">
		<visual>
			<geometry>
				<cylinder length="0.1240240552440719" radius="0.9002652240177268"/>
			</geometry>
		</visual>
		<collision>
			<geometry>
				<cylinder length="0.1240240552440719" radius="0.9002652240177268"/>
			</geometry>
		</collision>
		<inertial>
			<mass value="0.31578881875754206"/>
			<inertia ixx="0.03" iyy="0.03" izz="0.03" ixy="0" ixz="0" iyz="0"/>
		</inertial>
	</link>
	<link name="22">
		<visual>
			<geometry>
				<cylinder length="0.424163515513836" radius="0.503068739391497"/>
			</geometry>
		</visual>
		<collision>
			<geometry>
				<cylinder length="0.424163515513836" radius="0.503068739391497"/>
			</geometry>
		</collision>
		<inertial>
			<mass value="0.33723904045279574"/>
			<inertia ixx="0.03" iyy="0.03" izz="0.03" ixy="0" ixz="0" iyz="0"/>
		</inertial>
	</link>
	<link name="23">
		<visual>
			<geometry>
				<cylinder length="0.424163515513836" radius="0.503068739391497"/>
			</geometry>
		</visual>
		<collision>
			<geometry>
				<cylinder length="0.424163515513836" radius="0.503068739391497"/>
			</geometry>
		</collision>
		<inertial>
			<mass value="0.33723904045279574"/>
			<inertia ixx="0.03" iyy="0.03" izz="0.03" ixy="0" ixz="0" iyz="0"/>
		</inertial>
	</link>
	<link name="24">
		<visual>
			<geometry>
				<cylinder length="0.424163515513836" radius="0.503068739391497"/>
			</geometry>
		</visual>
		<collision>
			<geometry>
				<cylinder length="0.424163515513836" radius="0.503068739391497"/>
			</geometry>
		</collision>
		<inertial>
			<mass value="0.33723904045279574"/>
			<inertia ixx="0.03" iyy="0.03" izz="0.03" ixy="0" ixz="0" iyz="0"/>
		</inertial>
	</link>
	<link name="25">
		<visual>
			<geometry>
				<cylinder length="0.424163515513836" radius="0.503068739391497"/>
			</geometry>
		</visual>
		<collision>
			<geometry>
				<cylinder length="0.424163515513836" radius="0.503068739391497"/>
			</geometry>
		</collision>
		<inertial>
			<mass value="0.33723904045279574"/>
			<inertia ixx="0.03" iyy="0.03" izz="0.03" ixy="0" ixz="0" iyz="0"/>
		</inertial>
	</link>
	<joint name="11_to_0" type="revolute">
		<parent link="0"/>
		<child link="11"/>
		<axis xyz="0 1 0"/>
		<limit effort="1" lower="0" upper="1" velocity="1"/>
		<origin xyz="0.6958416647432165 0.004804272738273441 0.9201720907058762" rpy="1.2577299277350977 5.481256184935472 0.804077008332888"/>
	</joint>
	<joint name="22_to_11" type="fixed">
		<parent link="11"/>
		<child link="22"/>
		<axis xyz="0 1 0"/>
		<limit effort="1" lower="0" upper="1" velocity="1"/>
		<origin xyz="0.37305725530685707 0.4835058329245996 0.21216331655024723" rpy="5.93771435969809 3.6121558225623422 5.357360876711978"/>
	</joint>
	<joint name="23_to_11" type="fixed">
		<parent link="11"/>
		<child link="23"/>
		<axis xyz="0 1 0"/>
		<limit effort="1" lower="0" upper="1" velocity="1"/>
		<origin xyz="0.37305725530685707 0.4835058329245996 0.21216331655024723" rpy="8.906571539547134 3.6121558225623422 5.357360876711978"/>
	</joint>
	<joint name="24_to_11" type="fixed">
		<parent link="11"/>
		<child link="24"/>
		<axis xyz="0 1 0"/>
		<limit effort="1" lower="0" upper="1" velocity="1"/>
		<origin xyz="0.37305725530685707 0.4835058329245996 0.21216331655024723" rpy="11.87542871939618 3.6121558225623422 5.357360876711978"/>
	</joint>
	<joint name="25_to_11" type="fixed">
		<parent link="11"/>
		<child link="25"/>
		<axis xyz="0 1 0"/>
		<limit effort="1" lower="0" upper="1" velocity="1"/>
		<origin xyz="0.37305725530685707 0.4835058329245996 0.21216331655024723" rpy="14.844285899245225 3.6121558225623422 5.357360876711978"/>
	</joint>
</robot>
