<?xml version = "1.0"?>
<robot name="creature">
	<link name="0">
		<visual>
			<geometry>
				<cylinder length="0.16909351415917828" radius="0.12554539603197934"/>
			</geometry>
		</visual>
		<collision>
			<geometry>
				<cylinder length="0.16909351415917828" radius="0.12554539603197934"/>
			</geometry>
		</collision>
		<inertial>
			<mass value="0.008372948203478787"/>
			<inertia ixx="0.03" iyy="0.03" izz="0.03" ixy="0" ixz="0" iyz="0"/>
		</inertial>
	</link>
	<link name="11">
		<visual>
			<geometry>
				<cylinder length="0.2846492868542808" radius="0.44039046235374935"/>
			</geometry>
		</visual>
		<collision>
			<geometry>
				<cylinder length="0.2846492868542808" radius="0.44039046235374935"/>
			</geometry>
		</collision>
		<inertial>
			<mass value="0.17343461569980534"/>
			<inertia ixx="0.03" iyy="0.03" izz="0.03" ixy="0" ixz="0" iyz="0"/>
		</inertial>
	</link>
	<link name="12">
		<visual>
			<geometry>
				<cylinder length="0.2846492868542808" radius="0.44039046235374935"/>
			</geometry>
		</visual>
		<collision>
			<geometry>
				<cylinder length="0.2846492868542808" radius="0.44039046235374935"/>
			</geometry>
		</collision>
		<inertial>
			<mass value="0.17343461569980534"/>
			<inertia ixx="0.03" iyy="0.03" izz="0.03" ixy="0" ixz="0" iyz="0"/>
		</inertial>
	</link>
	<link name="13">
		<visual>
			<geometry>
				<cylinder length="0.2846492868542808" radius="0.44039046235374935"/>
			</geometry>
		</visual>
		<collision>
			<geometry>
				<cylinder length="0.2846492868542808" radius="0.44039046235374935"/>
			</geometry>
		</collision>
		<inertial>
			<mass value="0.17343461569980534"/>
			<inertia ixx="0.03" iyy="0.03" izz="0.03" ixy="0" ixz="0" iyz="0"/>
		</inertial>
	</link>
	<link name="14">
		<visual>
			<geometry>
				<cylinder length="0.2846492868542808" radius="0.44039046235374935"/>
			</geometry>
		</visual>
		<collision>
			<geometry>
				<cylinder length="0.2846492868542808" radius="0.44039046235374935"/>
			</geometry>
		</collision>
		<inertial>
			<mass value="0.17343461569980534"/>
			<inertia ixx="0.03" iyy="0.03" izz="0.03" ixy="0" ixz="0" iyz="0"/>
		</inertial>
	</link>
	<link name="25">
		<visual>
			<geometry>
				<cylinder length="0.479149652014801" radius="0.9020221052056012"/>
			</geometry>
		</visual>
		<collision>
			<geometry>
				<cylinder length="0.479149652014801" radius="0.9020221052056012"/>
			</geometry>
		</collision>
		<inertial>
			<mass value="1.224772456223729"/>
			<inertia ixx="0.03" iyy="0.03" izz="0.03" ixy="0" ixz="0" iyz="0"/>
		</inertial>
	</link>
	<joint name="11_to_0" type="revolute">
		<parent link="0"/>
		<child link="11"/>
		<axis xyz="1 0 0"/>
		<limit effort="1" lower="0" upper="1" velocity="1"/>
		<origin xyz="0.7997268607936372 0.5388188938303738 0.6976420407981926" rpy="11.384458300480272 0.816208611836453 6.215073736786412"/>
	</joint>
	<joint name="12_to_0" type="revolute">
		<parent link="0"/>
		<child link="12"/>
		<axis xyz="1 0 0"/>
		<limit effort="1" lower="0" upper="1" velocity="1"/>
		<origin xyz="0.7997268607936372 0.5388188938303738 0.6976420407981926" rpy="17.076687450720407 0.816208611836453 6.215073736786412"/>
	</joint>
	<joint name="13_to_0" type="revolute">
		<parent link="0"/>
		<child link="13"/>
		<axis xyz="1 0 0"/>
		<limit effort="1" lower="0" upper="1" velocity="1"/>
		<origin xyz="0.7997268607936372 0.5388188938303738 0.6976420407981926" rpy="22.768916600960544 0.816208611836453 6.215073736786412"/>
	</joint>
	<joint name="14_to_0" type="revolute">
		<parent link="0"/>
		<child link="14"/>
		<axis xyz="1 0 0"/>
		<limit effort="1" lower="0" upper="1" velocity="1"/>
		<origin xyz="0.7997268607936372 0.5388188938303738 0.6976420407981926" rpy="28.461145751200682 0.816208611836453 6.215073736786412"/>
	</joint>
	<joint name="25_to_0" type="fixed">
		<parent link="0"/>
		<child link="25"/>
		<axis xyz="1 0 0"/>
		<limit effort="1" lower="0" upper="1" velocity="1"/>
		<origin xyz="0.1664432173552205 0.6254807393135818 0.5140311348546337" rpy="10.396541789598285 1.3211997606909127 1.566092005974654"/>
	</joint>
</robot>
