<?xml version = "1.0"?>
<robot name="creature">
	<link name="0">
		<visual>
			<geometry>
				<cylinder length="0.18905473679604812" radius="0.48738784874599594"/>
			</geometry>
		</visual>
		<collision>
			<geometry>
				<cylinder length="0.18905473679604812" radius="0.48738784874599594"/>
			</geometry>
		</collision>
		<inertial>
			<mass value="0.14108694533604818"/>
			<inertia ixx="0.03" iyy="0.03" izz="0.03" ixy="0" ixz="0" iyz="0"/>
		</inertial>
	</link>
	<link name="11">
		<visual>
			<geometry>
				<cylinder length="0.9357555278405758" radius="0.5654253288916873"/>
			</geometry>
		</visual>
		<collision>
			<geometry>
				<cylinder length="0.9357555278405758" radius="0.5654253288916873"/>
			</geometry>
		</collision>
		<inertial>
			<mass value="0.93985919070154"/>
			<inertia ixx="0.03" iyy="0.03" izz="0.03" ixy="0" ixz="0" iyz="0"/>
		</inertial>
	</link>
	<link name="62">
		<visual>
			<geometry>
				<cylinder length="0.4540037818462106" radius="0.8046767128815087"/>
			</geometry>
		</visual>
		<collision>
			<geometry>
				<cylinder length="0.4540037818462106" radius="0.8046767128815087"/>
			</geometry>
		</collision>
		<inertial>
			<mass value="0.9235325558074189"/>
			<inertia ixx="0.03" iyy="0.03" izz="0.03" ixy="0" ixz="0" iyz="0"/>
		</inertial>
	</link>
	<link name="63">
		<visual>
			<geometry>
				<cylinder length="0.4540037818462106" radius="0.8046767128815087"/>
			</geometry>
		</visual>
		<collision>
			<geometry>
				<cylinder length="0.4540037818462106" radius="0.8046767128815087"/>
			</geometry>
		</collision>
		<inertial>
			<mass value="0.9235325558074189"/>
			<inertia ixx="0.03" iyy="0.03" izz="0.03" ixy="0" ixz="0" iyz="0"/>
		</inertial>
	</link>
	<link name="64">
		<visual>
			<geometry>
				<cylinder length="0.4540037818462106" radius="0.8046767128815087"/>
			</geometry>
		</visual>
		<collision>
			<geometry>
				<cylinder length="0.4540037818462106" radius="0.8046767128815087"/>
			</geometry>
		</collision>
		<inertial>
			<mass value="0.9235325558074189"/>
			<inertia ixx="0.03" iyy="0.03" izz="0.03" ixy="0" ixz="0" iyz="0"/>
		</inertial>
	</link>
	<link name="65">
		<visual>
			<geometry>
				<cylinder length="0.4540037818462106" radius="0.8046767128815087"/>
			</geometry>
		</visual>
		<collision>
			<geometry>
				<cylinder length="0.4540037818462106" radius="0.8046767128815087"/>
			</geometry>
		</collision>
		<inertial>
			<mass value="0.9235325558074189"/>
			<inertia ixx="0.03" iyy="0.03" izz="0.03" ixy="0" ixz="0" iyz="0"/>
		</inertial>
	</link>
	<link name="26">
		<visual>
			<geometry>
				<cylinder length="0.5388570301068938" radius="0.7843950416018497"/>
			</geometry>
		</visual>
		<collision>
			<geometry>
				<cylinder length="0.5388570301068938" radius="0.7843950416018497"/>
			</geometry>
		</collision>
		<inertial>
			<mass value="1.0415811346794177"/>
			<inertia ixx="0.03" iyy="0.03" izz="0.03" ixy="0" ixz="0" iyz="0"/>
		</inertial>
	</link>
	<link name="37">
		<visual>
			<geometry>
				<cylinder length="0.8491460811007498" radius="0.36888042486359485"/>
			</geometry>
		</visual>
		<collision>
			<geometry>
				<cylinder length="0.8491460811007498" radius="0.36888042486359485"/>
			</geometry>
		</collision>
		<inertial>
			<mass value="0.3629973889518482"/>
			<inertia ixx="0.03" iyy="0.03" izz="0.03" ixy="0" ixz="0" iyz="0"/>
		</inertial>
	</link>
	<link name="88">
		<visual>
			<geometry>
				<cylinder length="0.14002917744517884" radius="0.6853110595952986"/>
			</geometry>
		</visual>
		<collision>
			<geometry>
				<cylinder length="0.14002917744517884" radius="0.6853110595952986"/>
			</geometry>
		</collision>
		<inertial>
			<mass value="0.20660645758922314"/>
			<inertia ixx="0.03" iyy="0.03" izz="0.03" ixy="0" ixz="0" iyz="0"/>
		</inertial>
	</link>
	<link name="99">
		<visual>
			<geometry>
				<cylinder length="0.34987074120552963" radius="0.1943131607278824"/>
			</geometry>
		</visual>
		<collision>
			<geometry>
				<cylinder length="0.34987074120552963" radius="0.1943131607278824"/>
			</geometry>
		</collision>
		<inertial>
			<mass value="0.04150132189473505"/>
			<inertia ixx="0.03" iyy="0.03" izz="0.03" ixy="0" ixz="0" iyz="0"/>
		</inertial>
	</link>
	<link name="910">
		<visual>
			<geometry>
				<cylinder length="0.34987074120552963" radius="0.1943131607278824"/>
			</geometry>
		</visual>
		<collision>
			<geometry>
				<cylinder length="0.34987074120552963" radius="0.1943131607278824"/>
			</geometry>
		</collision>
		<inertial>
			<mass value="0.04150132189473505"/>
			<inertia ixx="0.03" iyy="0.03" izz="0.03" ixy="0" ixz="0" iyz="0"/>
		</inertial>
	</link>
	<link name="811">
		<visual>
			<geometry>
				<cylinder length="0.14002917744517884" radius="0.6853110595952986"/>
			</geometry>
		</visual>
		<collision>
			<geometry>
				<cylinder length="0.14002917744517884" radius="0.6853110595952986"/>
			</geometry>
		</collision>
		<inertial>
			<mass value="0.20660645758922314"/>
			<inertia ixx="0.03" iyy="0.03" izz="0.03" ixy="0" ixz="0" iyz="0"/>
		</inertial>
	</link>
	<link name="912">
		<visual>
			<geometry>
				<cylinder length="0.34987074120552963" radius="0.1943131607278824"/>
			</geometry>
		</visual>
		<collision>
			<geometry>
				<cylinder length="0.34987074120552963" radius="0.1943131607278824"/>
			</geometry>
		</collision>
		<inertial>
			<mass value="0.04150132189473505"/>
			<inertia ixx="0.03" iyy="0.03" izz="0.03" ixy="0" ixz="0" iyz="0"/>
		</inertial>
	</link>
	<link name="913">
		<visual>
			<geometry>
				<cylinder length="0.34987074120552963" radius="0.1943131607278824"/>
			</geometry>
		</visual>
		<collision>
			<geometry>
				<cylinder length="0.34987074120552963" radius="0.1943131607278824"/>
			</geometry>
		</collision>
		<inertial>
			<mass value="0.04150132189473505"/>
			<inertia ixx="0.03" iyy="0.03" izz="0.03" ixy="0" ixz="0" iyz="0"/>
		</inertial>
	</link>
	<link name="314">
		<visual>
			<geometry>
				<cylinder length="0.8491460811007498" radius="0.36888042486359485"/>
			</geometry>
		</visual>
		<collision>
			<geometry>
				<cylinder length="0.8491460811007498" radius="0.36888042486359485"/>
			</geometry>
		</collision>
		<inertial>
			<mass value="0.3629973889518482"/>
			<inertia ixx="0.03" iyy="0.03" izz="0.03" ixy="0" ixz="0" iyz="0"/>
		</inertial>
	</link>
	<link name="815">
		<visual>
			<geometry>
				<cylinder length="0.14002917744517884" radius="0.6853110595952986"/>
			</geometry>
		</visual>
		<collision>
			<geometry>
				<cylinder length="0.14002917744517884" radius="0.6853110595952986"/>
			</geometry>
		</collision>
		<inertial>
			<mass value="0.20660645758922314"/>
			<inertia ixx="0.03" iyy="0.03" izz="0.03" ixy="0" ixz="0" iyz="0"/>
		</inertial>
	</link>
	<link name="916">
		<visual>
			<geometry>
				<cylinder length="0.34987074120552963" radius="0.1943131607278824"/>
			</geometry>
		</visual>
		<collision>
			<geometry>
				<cylinder length="0.34987074120552963" radius="0.1943131607278824"/>
			</geometry>
		</collision>
		<inertial>
			<mass value="0.04150132189473505"/>
			<inertia ixx="0.03" iyy="0.03" izz="0.03" ixy="0" ixz="0" iyz="0"/>
		</inertial>
	</link>
	<link name="917">
		<visual>
			<geometry>
				<cylinder length="0.34987074120552963" radius="0.1943131607278824"/>
			</geometry>
		</visual>
		<collision>
			<geometry>
				<cylinder length="0.34987074120552963" radius="0.1943131607278824"/>
			</geometry>
		</collision>
		<inertial>
			<mass value="0.04150132189473505"/>
			<inertia ixx="0.03" iyy="0.03" izz="0.03" ixy="0" ixz="0" iyz="0"/>
		</inertial>
	</link>
	<link name="818">
		<visual>
			<geometry>
				<cylinder length="0.14002917744517884" radius="0.6853110595952986"/>
			</geometry>
		</visual>
		<collision>
			<geometry>
				<cylinder length="0.14002917744517884" radius="0.6853110595952986"/>
			</geometry>
		</collision>
		<inertial>
			<mass value="0.20660645758922314"/>
			<inertia ixx="0.03" iyy="0.03" izz="0.03" ixy="0" ixz="0" iyz="0"/>
		</inertial>
	</link>
	<link name="919">
		<visual>
			<geometry>
				<cylinder length="0.34987074120552963" radius="0.1943131607278824"/>
			</geometry>
		</visual>
		<collision>
			<geometry>
				<cylinder length="0.34987074120552963" radius="0.1943131607278824"/>
			</geometry>
		</collision>
		<inertial>
			<mass value="0.04150132189473505"/>
			<inertia ixx="0.03" iyy="0.03" izz="0.03" ixy="0" ixz="0" iyz="0"/>
		</inertial>
	</link>
	<link name="920">
		<visual>
			<geometry>
				<cylinder length="0.34987074120552963" radius="0.1943131607278824"/>
			</geometry>
		</visual>
		<collision>
			<geometry>
				<cylinder length="0.34987074120552963" radius="0.1943131607278824"/>
			</geometry>
		</collision>
		<inertial>
			<mass value="0.04150132189473505"/>
			<inertia ixx="0.03" iyy="0.03" izz="0.03" ixy="0" ixz="0" iyz="0"/>
		</inertial>
	</link>
	<link name="321">
		<visual>
			<geometry>
				<cylinder length="0.8491460811007498" radius="0.36888042486359485"/>
			</geometry>
		</visual>
		<collision>
			<geometry>
				<cylinder length="0.8491460811007498" radius="0.36888042486359485"/>
			</geometry>
		</collision>
		<inertial>
			<mass value="0.3629973889518482"/>
			<inertia ixx="0.03" iyy="0.03" izz="0.03" ixy="0" ixz="0" iyz="0"/>
		</inertial>
	</link>
	<link name="822">
		<visual>
			<geometry>
				<cylinder length="0.14002917744517884" radius="0.6853110595952986"/>
			</geometry>
		</visual>
		<collision>
			<geometry>
				<cylinder length="0.14002917744517884" radius="0.6853110595952986"/>
			</geometry>
		</collision>
		<inertial>
			<mass value="0.20660645758922314"/>
			<inertia ixx="0.03" iyy="0.03" izz="0.03" ixy="0" ixz="0" iyz="0"/>
		</inertial>
	</link>
	<link name="923">
		<visual>
			<geometry>
				<cylinder length="0.34987074120552963" radius="0.1943131607278824"/>
			</geometry>
		</visual>
		<collision>
			<geometry>
				<cylinder length="0.34987074120552963" radius="0.1943131607278824"/>
			</geometry>
		</collision>
		<inertial>
			<mass value="0.04150132189473505"/>
			<inertia ixx="0.03" iyy="0.03" izz="0.03" ixy="0" ixz="0" iyz="0"/>
		</inertial>
	</link>
	<link name="924">
		<visual>
			<geometry>
				<cylinder length="0.34987074120552963" radius="0.1943131607278824"/>
			</geometry>
		</visual>
		<collision>
			<geometry>
				<cylinder length="0.34987074120552963" radius="0.1943131607278824"/>
			</geometry>
		</collision>
		<inertial>
			<mass value="0.04150132189473505"/>
			<inertia ixx="0.03" iyy="0.03" izz="0.03" ixy="0" ixz="0" iyz="0"/>
		</inertial>
	</link>
	<link name="825">
		<visual>
			<geometry>
				<cylinder length="0.14002917744517884" radius="0.6853110595952986"/>
			</geometry>
		</visual>
		<collision>
			<geometry>
				<cylinder length="0.14002917744517884" radius="0.6853110595952986"/>
			</geometry>
		</collision>
		<inertial>
			<mass value="0.20660645758922314"/>
			<inertia ixx="0.03" iyy="0.03" izz="0.03" ixy="0" ixz="0" iyz="0"/>
		</inertial>
	</link>
	<link name="926">
		<visual>
			<geometry>
				<cylinder length="0.34987074120552963" radius="0.1943131607278824"/>
			</geometry>
		</visual>
		<collision>
			<geometry>
				<cylinder length="0.34987074120552963" radius="0.1943131607278824"/>
			</geometry>
		</collision>
		<inertial>
			<mass value="0.04150132189473505"/>
			<inertia ixx="0.03" iyy="0.03" izz="0.03" ixy="0" ixz="0" iyz="0"/>
		</inertial>
	</link>
	<link name="927">
		<visual>
			<geometry>
				<cylinder length="0.34987074120552963" radius="0.1943131607278824"/>
			</geometry>
		</visual>
		<collision>
			<geometry>
				<cylinder length="0.34987074120552963" radius="0.1943131607278824"/>
			</geometry>
		</collision>
		<inertial>
			<mass value="0.04150132189473505"/>
			<inertia ixx="0.03" iyy="0.03" izz="0.03" ixy="0" ixz="0" iyz="0"/>
		</inertial>
	</link>
	<link name="228">
		<visual>
			<geometry>
				<cylinder length="0.5388570301068938" radius="0.7843950416018497"/>
			</geometry>
		</visual>
		<collision>
			<geometry>
				<cylinder length="0.5388570301068938" radius="0.7843950416018497"/>
			</geometry>
		</collision>
		<inertial>
			<mass value="1.0415811346794177"/>
			<inertia ixx="0.03" iyy="0.03" izz="0.03" ixy="0" ixz="0" iyz="0"/>
		</inertial>
	</link>
	<link name="329">
		<visual>
			<geometry>
				<cylinder length="0.8491460811007498" radius="0.36888042486359485"/>
			</geometry>
		</visual>
		<collision>
			<geometry>
				<cylinder length="0.8491460811007498" radius="0.36888042486359485"/>
			</geometry>
		</collision>
		<inertial>
			<mass value="0.3629973889518482"/>
			<inertia ixx="0.03" iyy="0.03" izz="0.03" ixy="0" ixz="0" iyz="0"/>
		</inertial>
	</link>
	<link name="830">
		<visual>
			<geometry>
				<cylinder length="0.14002917744517884" radius="0.6853110595952986"/>
			</geometry>
		</visual>
		<collision>
			<geometry>
				<cylinder length="0.14002917744517884" radius="0.6853110595952986"/>
			</geometry>
		</collision>
		<inertial>
			<mass value="0.20660645758922314"/>
			<inertia ixx="0.03" iyy="0.03" izz="0.03" ixy="0" ixz="0" iyz="0"/>
		</inertial>
	</link>
	<link name="931">
		<visual>
			<geometry>
				<cylinder length="0.34987074120552963" radius="0.1943131607278824"/>
			</geometry>
		</visual>
		<collision>
			<geometry>
				<cylinder length="0.34987074120552963" radius="0.1943131607278824"/>
			</geometry>
		</collision>
		<inertial>
			<mass value="0.04150132189473505"/>
			<inertia ixx="0.03" iyy="0.03" izz="0.03" ixy="0" ixz="0" iyz="0"/>
		</inertial>
	</link>
	<link name="932">
		<visual>
			<geometry>
				<cylinder length="0.34987074120552963" radius="0.1943131607278824"/>
			</geometry>
		</visual>
		<collision>
			<geometry>
				<cylinder length="0.34987074120552963" radius="0.1943131607278824"/>
			</geometry>
		</collision>
		<inertial>
			<mass value="0.04150132189473505"/>
			<inertia ixx="0.03" iyy="0.03" izz="0.03" ixy="0" ixz="0" iyz="0"/>
		</inertial>
	</link>
	<link name="833">
		<visual>
			<geometry>
				<cylinder length="0.14002917744517884" radius="0.6853110595952986"/>
			</geometry>
		</visual>
		<collision>
			<geometry>
				<cylinder length="0.14002917744517884" radius="0.6853110595952986"/>
			</geometry>
		</collision>
		<inertial>
			<mass value="0.20660645758922314"/>
			<inertia ixx="0.03" iyy="0.03" izz="0.03" ixy="0" ixz="0" iyz="0"/>
		</inertial>
	</link>
	<link name="934">
		<visual>
			<geometry>
				<cylinder length="0.34987074120552963" radius="0.1943131607278824"/>
			</geometry>
		</visual>
		<collision>
			<geometry>
				<cylinder length="0.34987074120552963" radius="0.1943131607278824"/>
			</geometry>
		</collision>
		<inertial>
			<mass value="0.04150132189473505"/>
			<inertia ixx="0.03" iyy="0.03" izz="0.03" ixy="0" ixz="0" iyz="0"/>
		</inertial>
	</link>
	<link name="935">
		<visual>
			<geometry>
				<cylinder length="0.34987074120552963" radius="0.1943131607278824"/>
			</geometry>
		</visual>
		<collision>
			<geometry>
				<cylinder length="0.34987074120552963" radius="0.1943131607278824"/>
			</geometry>
		</collision>
		<inertial>
			<mass value="0.04150132189473505"/>
			<inertia ixx="0.03" iyy="0.03" izz="0.03" ixy="0" ixz="0" iyz="0"/>
		</inertial>
	</link>
	<link name="336">
		<visual>
			<geometry>
				<cylinder length="0.8491460811007498" radius="0.36888042486359485"/>
			</geometry>
		</visual>
		<collision>
			<geometry>
				<cylinder length="0.8491460811007498" radius="0.36888042486359485"/>
			</geometry>
		</collision>
		<inertial>
			<mass value="0.3629973889518482"/>
			<inertia ixx="0.03" iyy="0.03" izz="0.03" ixy="0" ixz="0" iyz="0"/>
		</inertial>
	</link>
	<link name="837">
		<visual>
			<geometry>
				<cylinder length="0.14002917744517884" radius="0.6853110595952986"/>
			</geometry>
		</visual>
		<collision>
			<geometry>
				<cylinder length="0.14002917744517884" radius="0.6853110595952986"/>
			</geometry>
		</collision>
		<inertial>
			<mass value="0.20660645758922314"/>
			<inertia ixx="0.03" iyy="0.03" izz="0.03" ixy="0" ixz="0" iyz="0"/>
		</inertial>
	</link>
	<link name="938">
		<visual>
			<geometry>
				<cylinder length="0.34987074120552963" radius="0.1943131607278824"/>
			</geometry>
		</visual>
		<collision>
			<geometry>
				<cylinder length="0.34987074120552963" radius="0.1943131607278824"/>
			</geometry>
		</collision>
		<inertial>
			<mass value="0.04150132189473505"/>
			<inertia ixx="0.03" iyy="0.03" izz="0.03" ixy="0" ixz="0" iyz="0"/>
		</inertial>
	</link>
	<link name="939">
		<visual>
			<geometry>
				<cylinder length="0.34987074120552963" radius="0.1943131607278824"/>
			</geometry>
		</visual>
		<collision>
			<geometry>
				<cylinder length="0.34987074120552963" radius="0.1943131607278824"/>
			</geometry>
		</collision>
		<inertial>
			<mass value="0.04150132189473505"/>
			<inertia ixx="0.03" iyy="0.03" izz="0.03" ixy="0" ixz="0" iyz="0"/>
		</inertial>
	</link>
	<link name="840">
		<visual>
			<geometry>
				<cylinder length="0.14002917744517884" radius="0.6853110595952986"/>
			</geometry>
		</visual>
		<collision>
			<geometry>
				<cylinder length="0.14002917744517884" radius="0.6853110595952986"/>
			</geometry>
		</collision>
		<inertial>
			<mass value="0.20660645758922314"/>
			<inertia ixx="0.03" iyy="0.03" izz="0.03" ixy="0" ixz="0" iyz="0"/>
		</inertial>
	</link>
	<link name="941">
		<visual>
			<geometry>
				<cylinder length="0.34987074120552963" radius="0.1943131607278824"/>
			</geometry>
		</visual>
		<collision>
			<geometry>
				<cylinder length="0.34987074120552963" radius="0.1943131607278824"/>
			</geometry>
		</collision>
		<inertial>
			<mass value="0.04150132189473505"/>
			<inertia ixx="0.03" iyy="0.03" izz="0.03" ixy="0" ixz="0" iyz="0"/>
		</inertial>
	</link>
	<link name="942">
		<visual>
			<geometry>
				<cylinder length="0.34987074120552963" radius="0.1943131607278824"/>
			</geometry>
		</visual>
		<collision>
			<geometry>
				<cylinder length="0.34987074120552963" radius="0.1943131607278824"/>
			</geometry>
		</collision>
		<inertial>
			<mass value="0.04150132189473505"/>
			<inertia ixx="0.03" iyy="0.03" izz="0.03" ixy="0" ixz="0" iyz="0"/>
		</inertial>
	</link>
	<link name="343">
		<visual>
			<geometry>
				<cylinder length="0.8491460811007498" radius="0.36888042486359485"/>
			</geometry>
		</visual>
		<collision>
			<geometry>
				<cylinder length="0.8491460811007498" radius="0.36888042486359485"/>
			</geometry>
		</collision>
		<inertial>
			<mass value="0.3629973889518482"/>
			<inertia ixx="0.03" iyy="0.03" izz="0.03" ixy="0" ixz="0" iyz="0"/>
		</inertial>
	</link>
	<link name="844">
		<visual>
			<geometry>
				<cylinder length="0.14002917744517884" radius="0.6853110595952986"/>
			</geometry>
		</visual>
		<collision>
			<geometry>
				<cylinder length="0.14002917744517884" radius="0.6853110595952986"/>
			</geometry>
		</collision>
		<inertial>
			<mass value="0.20660645758922314"/>
			<inertia ixx="0.03" iyy="0.03" izz="0.03" ixy="0" ixz="0" iyz="0"/>
		</inertial>
	</link>
	<link name="945">
		<visual>
			<geometry>
				<cylinder length="0.34987074120552963" radius="0.1943131607278824"/>
			</geometry>
		</visual>
		<collision>
			<geometry>
				<cylinder length="0.34987074120552963" radius="0.1943131607278824"/>
			</geometry>
		</collision>
		<inertial>
			<mass value="0.04150132189473505"/>
			<inertia ixx="0.03" iyy="0.03" izz="0.03" ixy="0" ixz="0" iyz="0"/>
		</inertial>
	</link>
	<link name="946">
		<visual>
			<geometry>
				<cylinder length="0.34987074120552963" radius="0.1943131607278824"/>
			</geometry>
		</visual>
		<collision>
			<geometry>
				<cylinder length="0.34987074120552963" radius="0.1943131607278824"/>
			</geometry>
		</collision>
		<inertial>
			<mass value="0.04150132189473505"/>
			<inertia ixx="0.03" iyy="0.03" izz="0.03" ixy="0" ixz="0" iyz="0"/>
		</inertial>
	</link>
	<link name="847">
		<visual>
			<geometry>
				<cylinder length="0.14002917744517884" radius="0.6853110595952986"/>
			</geometry>
		</visual>
		<collision>
			<geometry>
				<cylinder length="0.14002917744517884" radius="0.6853110595952986"/>
			</geometry>
		</collision>
		<inertial>
			<mass value="0.20660645758922314"/>
			<inertia ixx="0.03" iyy="0.03" izz="0.03" ixy="0" ixz="0" iyz="0"/>
		</inertial>
	</link>
	<link name="948">
		<visual>
			<geometry>
				<cylinder length="0.34987074120552963" radius="0.1943131607278824"/>
			</geometry>
		</visual>
		<collision>
			<geometry>
				<cylinder length="0.34987074120552963" radius="0.1943131607278824"/>
			</geometry>
		</collision>
		<inertial>
			<mass value="0.04150132189473505"/>
			<inertia ixx="0.03" iyy="0.03" izz="0.03" ixy="0" ixz="0" iyz="0"/>
		</inertial>
	</link>
	<link name="949">
		<visual>
			<geometry>
				<cylinder length="0.34987074120552963" radius="0.1943131607278824"/>
			</geometry>
		</visual>
		<collision>
			<geometry>
				<cylinder length="0.34987074120552963" radius="0.1943131607278824"/>
			</geometry>
		</collision>
		<inertial>
			<mass value="0.04150132189473505"/>
			<inertia ixx="0.03" iyy="0.03" izz="0.03" ixy="0" ixz="0" iyz="0"/>
		</inertial>
	</link>
	<link name="250">
		<visual>
			<geometry>
				<cylinder length="0.5388570301068938" radius="0.7843950416018497"/>
			</geometry>
		</visual>
		<collision>
			<geometry>
				<cylinder length="0.5388570301068938" radius="0.7843950416018497"/>
			</geometry>
		</collision>
		<inertial>
			<mass value="1.0415811346794177"/>
			<inertia ixx="0.03" iyy="0.03" izz="0.03" ixy="0" ixz="0" iyz="0"/>
		</inertial>
	</link>
	<link name="351">
		<visual>
			<geometry>
				<cylinder length="0.8491460811007498" radius="0.36888042486359485"/>
			</geometry>
		</visual>
		<collision>
			<geometry>
				<cylinder length="0.8491460811007498" radius="0.36888042486359485"/>
			</geometry>
		</collision>
		<inertial>
			<mass value="0.3629973889518482"/>
			<inertia ixx="0.03" iyy="0.03" izz="0.03" ixy="0" ixz="0" iyz="0"/>
		</inertial>
	</link>
	<link name="852">
		<visual>
			<geometry>
				<cylinder length="0.14002917744517884" radius="0.6853110595952986"/>
			</geometry>
		</visual>
		<collision>
			<geometry>
				<cylinder length="0.14002917744517884" radius="0.6853110595952986"/>
			</geometry>
		</collision>
		<inertial>
			<mass value="0.20660645758922314"/>
			<inertia ixx="0.03" iyy="0.03" izz="0.03" ixy="0" ixz="0" iyz="0"/>
		</inertial>
	</link>
	<link name="953">
		<visual>
			<geometry>
				<cylinder length="0.34987074120552963" radius="0.1943131607278824"/>
			</geometry>
		</visual>
		<collision>
			<geometry>
				<cylinder length="0.34987074120552963" radius="0.1943131607278824"/>
			</geometry>
		</collision>
		<inertial>
			<mass value="0.04150132189473505"/>
			<inertia ixx="0.03" iyy="0.03" izz="0.03" ixy="0" ixz="0" iyz="0"/>
		</inertial>
	</link>
	<link name="954">
		<visual>
			<geometry>
				<cylinder length="0.34987074120552963" radius="0.1943131607278824"/>
			</geometry>
		</visual>
		<collision>
			<geometry>
				<cylinder length="0.34987074120552963" radius="0.1943131607278824"/>
			</geometry>
		</collision>
		<inertial>
			<mass value="0.04150132189473505"/>
			<inertia ixx="0.03" iyy="0.03" izz="0.03" ixy="0" ixz="0" iyz="0"/>
		</inertial>
	</link>
	<link name="855">
		<visual>
			<geometry>
				<cylinder length="0.14002917744517884" radius="0.6853110595952986"/>
			</geometry>
		</visual>
		<collision>
			<geometry>
				<cylinder length="0.14002917744517884" radius="0.6853110595952986"/>
			</geometry>
		</collision>
		<inertial>
			<mass value="0.20660645758922314"/>
			<inertia ixx="0.03" iyy="0.03" izz="0.03" ixy="0" ixz="0" iyz="0"/>
		</inertial>
	</link>
	<link name="956">
		<visual>
			<geometry>
				<cylinder length="0.34987074120552963" radius="0.1943131607278824"/>
			</geometry>
		</visual>
		<collision>
			<geometry>
				<cylinder length="0.34987074120552963" radius="0.1943131607278824"/>
			</geometry>
		</collision>
		<inertial>
			<mass value="0.04150132189473505"/>
			<inertia ixx="0.03" iyy="0.03" izz="0.03" ixy="0" ixz="0" iyz="0"/>
		</inertial>
	</link>
	<link name="957">
		<visual>
			<geometry>
				<cylinder length="0.34987074120552963" radius="0.1943131607278824"/>
			</geometry>
		</visual>
		<collision>
			<geometry>
				<cylinder length="0.34987074120552963" radius="0.1943131607278824"/>
			</geometry>
		</collision>
		<inertial>
			<mass value="0.04150132189473505"/>
			<inertia ixx="0.03" iyy="0.03" izz="0.03" ixy="0" ixz="0" iyz="0"/>
		</inertial>
	</link>
	<link name="358">
		<visual>
			<geometry>
				<cylinder length="0.8491460811007498" radius="0.36888042486359485"/>
			</geometry>
		</visual>
		<collision>
			<geometry>
				<cylinder length="0.8491460811007498" radius="0.36888042486359485"/>
			</geometry>
		</collision>
		<inertial>
			<mass value="0.3629973889518482"/>
			<inertia ixx="0.03" iyy="0.03" izz="0.03" ixy="0" ixz="0" iyz="0"/>
		</inertial>
	</link>
	<link name="859">
		<visual>
			<geometry>
				<cylinder length="0.14002917744517884" radius="0.6853110595952986"/>
			</geometry>
		</visual>
		<collision>
			<geometry>
				<cylinder length="0.14002917744517884" radius="0.6853110595952986"/>
			</geometry>
		</collision>
		<inertial>
			<mass value="0.20660645758922314"/>
			<inertia ixx="0.03" iyy="0.03" izz="0.03" ixy="0" ixz="0" iyz="0"/>
		</inertial>
	</link>
	<link name="960">
		<visual>
			<geometry>
				<cylinder length="0.34987074120552963" radius="0.1943131607278824"/>
			</geometry>
		</visual>
		<collision>
			<geometry>
				<cylinder length="0.34987074120552963" radius="0.1943131607278824"/>
			</geometry>
		</collision>
		<inertial>
			<mass value="0.04150132189473505"/>
			<inertia ixx="0.03" iyy="0.03" izz="0.03" ixy="0" ixz="0" iyz="0"/>
		</inertial>
	</link>
	<link name="961">
		<visual>
			<geometry>
				<cylinder length="0.34987074120552963" radius="0.1943131607278824"/>
			</geometry>
		</visual>
		<collision>
			<geometry>
				<cylinder length="0.34987074120552963" radius="0.1943131607278824"/>
			</geometry>
		</collision>
		<inertial>
			<mass value="0.04150132189473505"/>
			<inertia ixx="0.03" iyy="0.03" izz="0.03" ixy="0" ixz="0" iyz="0"/>
		</inertial>
	</link>
	<link name="862">
		<visual>
			<geometry>
				<cylinder length="0.14002917744517884" radius="0.6853110595952986"/>
			</geometry>
		</visual>
		<collision>
			<geometry>
				<cylinder length="0.14002917744517884" radius="0.6853110595952986"/>
			</geometry>
		</collision>
		<inertial>
			<mass value="0.20660645758922314"/>
			<inertia ixx="0.03" iyy="0.03" izz="0.03" ixy="0" ixz="0" iyz="0"/>
		</inertial>
	</link>
	<link name="963">
		<visual>
			<geometry>
				<cylinder length="0.34987074120552963" radius="0.1943131607278824"/>
			</geometry>
		</visual>
		<collision>
			<geometry>
				<cylinder length="0.34987074120552963" radius="0.1943131607278824"/>
			</geometry>
		</collision>
		<inertial>
			<mass value="0.04150132189473505"/>
			<inertia ixx="0.03" iyy="0.03" izz="0.03" ixy="0" ixz="0" iyz="0"/>
		</inertial>
	</link>
	<link name="964">
		<visual>
			<geometry>
				<cylinder length="0.34987074120552963" radius="0.1943131607278824"/>
			</geometry>
		</visual>
		<collision>
			<geometry>
				<cylinder length="0.34987074120552963" radius="0.1943131607278824"/>
			</geometry>
		</collision>
		<inertial>
			<mass value="0.04150132189473505"/>
			<inertia ixx="0.03" iyy="0.03" izz="0.03" ixy="0" ixz="0" iyz="0"/>
		</inertial>
	</link>
	<link name="365">
		<visual>
			<geometry>
				<cylinder length="0.8491460811007498" radius="0.36888042486359485"/>
			</geometry>
		</visual>
		<collision>
			<geometry>
				<cylinder length="0.8491460811007498" radius="0.36888042486359485"/>
			</geometry>
		</collision>
		<inertial>
			<mass value="0.3629973889518482"/>
			<inertia ixx="0.03" iyy="0.03" izz="0.03" ixy="0" ixz="0" iyz="0"/>
		</inertial>
	</link>
	<link name="866">
		<visual>
			<geometry>
				<cylinder length="0.14002917744517884" radius="0.6853110595952986"/>
			</geometry>
		</visual>
		<collision>
			<geometry>
				<cylinder length="0.14002917744517884" radius="0.6853110595952986"/>
			</geometry>
		</collision>
		<inertial>
			<mass value="0.20660645758922314"/>
			<inertia ixx="0.03" iyy="0.03" izz="0.03" ixy="0" ixz="0" iyz="0"/>
		</inertial>
	</link>
	<link name="967">
		<visual>
			<geometry>
				<cylinder length="0.34987074120552963" radius="0.1943131607278824"/>
			</geometry>
		</visual>
		<collision>
			<geometry>
				<cylinder length="0.34987074120552963" radius="0.1943131607278824"/>
			</geometry>
		</collision>
		<inertial>
			<mass value="0.04150132189473505"/>
			<inertia ixx="0.03" iyy="0.03" izz="0.03" ixy="0" ixz="0" iyz="0"/>
		</inertial>
	</link>
	<link name="968">
		<visual>
			<geometry>
				<cylinder length="0.34987074120552963" radius="0.1943131607278824"/>
			</geometry>
		</visual>
		<collision>
			<geometry>
				<cylinder length="0.34987074120552963" radius="0.1943131607278824"/>
			</geometry>
		</collision>
		<inertial>
			<mass value="0.04150132189473505"/>
			<inertia ixx="0.03" iyy="0.03" izz="0.03" ixy="0" ixz="0" iyz="0"/>
		</inertial>
	</link>
	<link name="869">
		<visual>
			<geometry>
				<cylinder length="0.14002917744517884" radius="0.6853110595952986"/>
			</geometry>
		</visual>
		<collision>
			<geometry>
				<cylinder length="0.14002917744517884" radius="0.6853110595952986"/>
			</geometry>
		</collision>
		<inertial>
			<mass value="0.20660645758922314"/>
			<inertia ixx="0.03" iyy="0.03" izz="0.03" ixy="0" ixz="0" iyz="0"/>
		</inertial>
	</link>
	<link name="970">
		<visual>
			<geometry>
				<cylinder length="0.34987074120552963" radius="0.1943131607278824"/>
			</geometry>
		</visual>
		<collision>
			<geometry>
				<cylinder length="0.34987074120552963" radius="0.1943131607278824"/>
			</geometry>
		</collision>
		<inertial>
			<mass value="0.04150132189473505"/>
			<inertia ixx="0.03" iyy="0.03" izz="0.03" ixy="0" ixz="0" iyz="0"/>
		</inertial>
	</link>
	<link name="971">
		<visual>
			<geometry>
				<cylinder length="0.34987074120552963" radius="0.1943131607278824"/>
			</geometry>
		</visual>
		<collision>
			<geometry>
				<cylinder length="0.34987074120552963" radius="0.1943131607278824"/>
			</geometry>
		</collision>
		<inertial>
			<mass value="0.04150132189473505"/>
			<inertia ixx="0.03" iyy="0.03" izz="0.03" ixy="0" ixz="0" iyz="0"/>
		</inertial>
	</link>
	<link name="472">
		<visual>
			<geometry>
				<cylinder length="0.6582641791222774" radius="0.8606667092681237"/>
			</geometry>
		</visual>
		<collision>
			<geometry>
				<cylinder length="0.6582641791222774" radius="0.8606667092681237"/>
			</geometry>
		</collision>
		<inertial>
			<mass value="1.5318636287111305"/>
			<inertia ixx="0.03" iyy="0.03" izz="0.03" ixy="0" ixz="0" iyz="0"/>
		</inertial>
	</link>
	<link name="573">
		<visual>
			<geometry>
				<cylinder length="0.34129125092841894" radius="0.2652493946155461"/>
			</geometry>
		</visual>
		<collision>
			<geometry>
				<cylinder length="0.34129125092841894" radius="0.2652493946155461"/>
			</geometry>
		</collision>
		<inertial>
			<mass value="0.07543689955100037"/>
			<inertia ixx="0.03" iyy="0.03" izz="0.03" ixy="0" ixz="0" iyz="0"/>
		</inertial>
	</link>
	<link name="774">
		<visual>
			<geometry>
				<cylinder length="0.6321126495052369" radius="0.8067521914006643"/>
			</geometry>
		</visual>
		<collision>
			<geometry>
				<cylinder length="0.6321126495052369" radius="0.8067521914006643"/>
			</geometry>
		</collision>
		<inertial>
			<mass value="1.292482470166766"/>
			<inertia ixx="0.03" iyy="0.03" izz="0.03" ixy="0" ixz="0" iyz="0"/>
		</inertial>
	</link>
	<link name="775">
		<visual>
			<geometry>
				<cylinder length="0.6321126495052369" radius="0.8067521914006643"/>
			</geometry>
		</visual>
		<collision>
			<geometry>
				<cylinder length="0.6321126495052369" radius="0.8067521914006643"/>
			</geometry>
		</collision>
		<inertial>
			<mass value="1.292482470166766"/>
			<inertia ixx="0.03" iyy="0.03" izz="0.03" ixy="0" ixz="0" iyz="0"/>
		</inertial>
	</link>
	<link name="776">
		<visual>
			<geometry>
				<cylinder length="0.6321126495052369" radius="0.8067521914006643"/>
			</geometry>
		</visual>
		<collision>
			<geometry>
				<cylinder length="0.6321126495052369" radius="0.8067521914006643"/>
			</geometry>
		</collision>
		<inertial>
			<mass value="1.292482470166766"/>
			<inertia ixx="0.03" iyy="0.03" izz="0.03" ixy="0" ixz="0" iyz="0"/>
		</inertial>
	</link>
	<joint name="11_to_0" type="fixed">
		<parent link="0"/>
		<child link="11"/>
		<axis xyz="1 0 0"/>
		<limit effort="1" lower="0" upper="1" velocity="1"/>
		<origin xyz="0.5533284721857961 0.36334476943027605 0.7277071491226799" rpy="8.761916008203615 3.842904219788735 5.07830415394838"/>
	</joint>
	<joint name="62_to_11" type="fixed">
		<parent link="11"/>
		<child link="62"/>
		<axis xyz="0 0 1"/>
		<limit effort="1" lower="0" upper="1" velocity="1"/>
		<origin xyz="0.9515647864338728 0.7232089959924445 0.873609772513541" rpy="7.001974746148975 4.722422002076133 2.62760796266902"/>
	</joint>
	<joint name="63_to_11" type="fixed">
		<parent link="11"/>
		<child link="63"/>
		<axis xyz="0 0 1"/>
		<limit effort="1" lower="0" upper="1" velocity="1"/>
		<origin xyz="0.9515647864338728 0.7232089959924445 0.873609772513541" rpy="10.502962119223463 4.722422002076133 2.62760796266902"/>
	</joint>
	<joint name="64_to_11" type="fixed">
		<parent link="11"/>
		<child link="64"/>
		<axis xyz="0 0 1"/>
		<limit effort="1" lower="0" upper="1" velocity="1"/>
		<origin xyz="0.9515647864338728 0.7232089959924445 0.873609772513541" rpy="14.00394949229795 4.722422002076133 2.62760796266902"/>
	</joint>
	<joint name="65_to_11" type="fixed">
		<parent link="11"/>
		<child link="65"/>
		<axis xyz="0 0 1"/>
		<limit effort="1" lower="0" upper="1" velocity="1"/>
		<origin xyz="0.9515647864338728 0.7232089959924445 0.873609772513541" rpy="17.50493686537244 4.722422002076133 2.62760796266902"/>
	</joint>
	<joint name="26_to_0" type="revolute">
		<parent link="0"/>
		<child link="26"/>
		<axis xyz="1 0 0"/>
		<limit effort="1" lower="0" upper="1" velocity="1"/>
		<origin xyz="0.3559143287974629 0.7831262154356912 0.884390288286699" rpy="8.071406930114753 5.329041761708994 4.499941867454197"/>
	</joint>
	<joint name="37_to_26" type="revolute">
		<parent link="26"/>
		<child link="37"/>
		<axis xyz="1 0 0"/>
		<limit effort="1" lower="0" upper="1" velocity="1"/>
		<origin xyz="0.034789362477794517 0.8718791615597162 0.41043482191133807" rpy="9.806408306083924 3.944063460916242 1.10153216003229"/>
	</joint>
	<joint name="88_to_37" type="fixed">
		<parent link="37"/>
		<child link="88"/>
		<axis xyz="0 1 0"/>
		<limit effort="1" lower="0" upper="1" velocity="1"/>
		<origin xyz="0.9655793850913542 0.7355226604465349 0.9979723451106056" rpy="5.819854435280853 5.681016950828654 3.485998934322694"/>
	</joint>
	<joint name="99_to_88" type="revolute">
		<parent link="88"/>
		<child link="99"/>
		<axis xyz="1 0 0"/>
		<limit effort="1" lower="0" upper="1" velocity="1"/>
		<origin xyz="0.23720908794553752 0.048368111528088065 0.3970371629542918" rpy="10.085414229613912 5.214353602771387 2.779195427006664"/>
	</joint>
	<joint name="910_to_88" type="revolute">
		<parent link="88"/>
		<child link="910"/>
		<axis xyz="1 0 0"/>
		<limit effort="1" lower="0" upper="1" velocity="1"/>
		<origin xyz="0.23720908794553752 0.048368111528088065 0.3970371629542918" rpy="15.128121344420869 5.214353602771387 2.779195427006664"/>
	</joint>
	<joint name="811_to_37" type="fixed">
		<parent link="37"/>
		<child link="811"/>
		<axis xyz="0 1 0"/>
		<limit effort="1" lower="0" upper="1" velocity="1"/>
		<origin xyz="0.9655793850913542 0.7355226604465349 0.9979723451106056" rpy="8.729781652921279 5.681016950828654 3.485998934322694"/>
	</joint>
	<joint name="912_to_811" type="revolute">
		<parent link="811"/>
		<child link="912"/>
		<axis xyz="1 0 0"/>
		<limit effort="1" lower="0" upper="1" velocity="1"/>
		<origin xyz="0.23720908794553752 0.048368111528088065 0.3970371629542918" rpy="10.085414229613912 5.214353602771387 2.779195427006664"/>
	</joint>
	<joint name="913_to_811" type="revolute">
		<parent link="811"/>
		<child link="913"/>
		<axis xyz="1 0 0"/>
		<limit effort="1" lower="0" upper="1" velocity="1"/>
		<origin xyz="0.23720908794553752 0.048368111528088065 0.3970371629542918" rpy="15.128121344420869 5.214353602771387 2.779195427006664"/>
	</joint>
	<joint name="314_to_26" type="revolute">
		<parent link="26"/>
		<child link="314"/>
		<axis xyz="1 0 0"/>
		<limit effort="1" lower="0" upper="1" velocity="1"/>
		<origin xyz="0.034789362477794517 0.8718791615597162 0.41043482191133807" rpy="14.709612459125886 3.944063460916242 1.10153216003229"/>
	</joint>
	<joint name="815_to_314" type="fixed">
		<parent link="314"/>
		<child link="815"/>
		<axis xyz="0 1 0"/>
		<limit effort="1" lower="0" upper="1" velocity="1"/>
		<origin xyz="0.9655793850913542 0.7355226604465349 0.9979723451106056" rpy="5.819854435280853 5.681016950828654 3.485998934322694"/>
	</joint>
	<joint name="916_to_815" type="revolute">
		<parent link="815"/>
		<child link="916"/>
		<axis xyz="1 0 0"/>
		<limit effort="1" lower="0" upper="1" velocity="1"/>
		<origin xyz="0.23720908794553752 0.048368111528088065 0.3970371629542918" rpy="10.085414229613912 5.214353602771387 2.779195427006664"/>
	</joint>
	<joint name="917_to_815" type="revolute">
		<parent link="815"/>
		<child link="917"/>
		<axis xyz="1 0 0"/>
		<limit effort="1" lower="0" upper="1" velocity="1"/>
		<origin xyz="0.23720908794553752 0.048368111528088065 0.3970371629542918" rpy="15.128121344420869 5.214353602771387 2.779195427006664"/>
	</joint>
	<joint name="818_to_314" type="fixed">
		<parent link="314"/>
		<child link="818"/>
		<axis xyz="0 1 0"/>
		<limit effort="1" lower="0" upper="1" velocity="1"/>
		<origin xyz="0.9655793850913542 0.7355226604465349 0.9979723451106056" rpy="8.729781652921279 5.681016950828654 3.485998934322694"/>
	</joint>
	<joint name="919_to_818" type="revolute">
		<parent link="818"/>
		<child link="919"/>
		<axis xyz="1 0 0"/>
		<limit effort="1" lower="0" upper="1" velocity="1"/>
		<origin xyz="0.23720908794553752 0.048368111528088065 0.3970371629542918" rpy="10.085414229613912 5.214353602771387 2.779195427006664"/>
	</joint>
	<joint name="920_to_818" type="revolute">
		<parent link="818"/>
		<child link="920"/>
		<axis xyz="1 0 0"/>
		<limit effort="1" lower="0" upper="1" velocity="1"/>
		<origin xyz="0.23720908794553752 0.048368111528088065 0.3970371629542918" rpy="15.128121344420869 5.214353602771387 2.779195427006664"/>
	</joint>
	<joint name="321_to_26" type="revolute">
		<parent link="26"/>
		<child link="321"/>
		<axis xyz="1 0 0"/>
		<limit effort="1" lower="0" upper="1" velocity="1"/>
		<origin xyz="0.034789362477794517 0.8718791615597162 0.41043482191133807" rpy="19.612816612167848 3.944063460916242 1.10153216003229"/>
	</joint>
	<joint name="822_to_321" type="fixed">
		<parent link="321"/>
		<child link="822"/>
		<axis xyz="0 1 0"/>
		<limit effort="1" lower="0" upper="1" velocity="1"/>
		<origin xyz="0.9655793850913542 0.7355226604465349 0.9979723451106056" rpy="5.819854435280853 5.681016950828654 3.485998934322694"/>
	</joint>
	<joint name="923_to_822" type="revolute">
		<parent link="822"/>
		<child link="923"/>
		<axis xyz="1 0 0"/>
		<limit effort="1" lower="0" upper="1" velocity="1"/>
		<origin xyz="0.23720908794553752 0.048368111528088065 0.3970371629542918" rpy="10.085414229613912 5.214353602771387 2.779195427006664"/>
	</joint>
	<joint name="924_to_822" type="revolute">
		<parent link="822"/>
		<child link="924"/>
		<axis xyz="1 0 0"/>
		<limit effort="1" lower="0" upper="1" velocity="1"/>
		<origin xyz="0.23720908794553752 0.048368111528088065 0.3970371629542918" rpy="15.128121344420869 5.214353602771387 2.779195427006664"/>
	</joint>
	<joint name="825_to_321" type="fixed">
		<parent link="321"/>
		<child link="825"/>
		<axis xyz="0 1 0"/>
		<limit effort="1" lower="0" upper="1" velocity="1"/>
		<origin xyz="0.9655793850913542 0.7355226604465349 0.9979723451106056" rpy="8.729781652921279 5.681016950828654 3.485998934322694"/>
	</joint>
	<joint name="926_to_825" type="revolute">
		<parent link="825"/>
		<child link="926"/>
		<axis xyz="1 0 0"/>
		<limit effort="1" lower="0" upper="1" velocity="1"/>
		<origin xyz="0.23720908794553752 0.048368111528088065 0.3970371629542918" rpy="10.085414229613912 5.214353602771387 2.779195427006664"/>
	</joint>
	<joint name="927_to_825" type="revolute">
		<parent link="825"/>
		<child link="927"/>
		<axis xyz="1 0 0"/>
		<limit effort="1" lower="0" upper="1" velocity="1"/>
		<origin xyz="0.23720908794553752 0.048368111528088065 0.3970371629542918" rpy="15.128121344420869 5.214353602771387 2.779195427006664"/>
	</joint>
	<joint name="228_to_0" type="revolute">
		<parent link="0"/>
		<child link="228"/>
		<axis xyz="1 0 0"/>
		<limit effort="1" lower="0" upper="1" velocity="1"/>
		<origin xyz="0.3559143287974629 0.7831262154356912 0.884390288286699" rpy="10.76187590681967 5.329041761708994 4.499941867454197"/>
	</joint>
	<joint name="329_to_228" type="revolute">
		<parent link="228"/>
		<child link="329"/>
		<axis xyz="1 0 0"/>
		<limit effort="1" lower="0" upper="1" velocity="1"/>
		<origin xyz="0.034789362477794517 0.8718791615597162 0.41043482191133807" rpy="9.806408306083924 3.944063460916242 1.10153216003229"/>
	</joint>
	<joint name="830_to_329" type="fixed">
		<parent link="329"/>
		<child link="830"/>
		<axis xyz="0 1 0"/>
		<limit effort="1" lower="0" upper="1" velocity="1"/>
		<origin xyz="0.9655793850913542 0.7355226604465349 0.9979723451106056" rpy="5.819854435280853 5.681016950828654 3.485998934322694"/>
	</joint>
	<joint name="931_to_830" type="revolute">
		<parent link="830"/>
		<child link="931"/>
		<axis xyz="1 0 0"/>
		<limit effort="1" lower="0" upper="1" velocity="1"/>
		<origin xyz="0.23720908794553752 0.048368111528088065 0.3970371629542918" rpy="10.085414229613912 5.214353602771387 2.779195427006664"/>
	</joint>
	<joint name="932_to_830" type="revolute">
		<parent link="830"/>
		<child link="932"/>
		<axis xyz="1 0 0"/>
		<limit effort="1" lower="0" upper="1" velocity="1"/>
		<origin xyz="0.23720908794553752 0.048368111528088065 0.3970371629542918" rpy="15.128121344420869 5.214353602771387 2.779195427006664"/>
	</joint>
	<joint name="833_to_329" type="fixed">
		<parent link="329"/>
		<child link="833"/>
		<axis xyz="0 1 0"/>
		<limit effort="1" lower="0" upper="1" velocity="1"/>
		<origin xyz="0.9655793850913542 0.7355226604465349 0.9979723451106056" rpy="8.729781652921279 5.681016950828654 3.485998934322694"/>
	</joint>
	<joint name="934_to_833" type="revolute">
		<parent link="833"/>
		<child link="934"/>
		<axis xyz="1 0 0"/>
		<limit effort="1" lower="0" upper="1" velocity="1"/>
		<origin xyz="0.23720908794553752 0.048368111528088065 0.3970371629542918" rpy="10.085414229613912 5.214353602771387 2.779195427006664"/>
	</joint>
	<joint name="935_to_833" type="revolute">
		<parent link="833"/>
		<child link="935"/>
		<axis xyz="1 0 0"/>
		<limit effort="1" lower="0" upper="1" velocity="1"/>
		<origin xyz="0.23720908794553752 0.048368111528088065 0.3970371629542918" rpy="15.128121344420869 5.214353602771387 2.779195427006664"/>
	</joint>
	<joint name="336_to_228" type="revolute">
		<parent link="228"/>
		<child link="336"/>
		<axis xyz="1 0 0"/>
		<limit effort="1" lower="0" upper="1" velocity="1"/>
		<origin xyz="0.034789362477794517 0.8718791615597162 0.41043482191133807" rpy="14.709612459125886 3.944063460916242 1.10153216003229"/>
	</joint>
	<joint name="837_to_336" type="fixed">
		<parent link="336"/>
		<child link="837"/>
		<axis xyz="0 1 0"/>
		<limit effort="1" lower="0" upper="1" velocity="1"/>
		<origin xyz="0.9655793850913542 0.7355226604465349 0.9979723451106056" rpy="5.819854435280853 5.681016950828654 3.485998934322694"/>
	</joint>
	<joint name="938_to_837" type="revolute">
		<parent link="837"/>
		<child link="938"/>
		<axis xyz="1 0 0"/>
		<limit effort="1" lower="0" upper="1" velocity="1"/>
		<origin xyz="0.23720908794553752 0.048368111528088065 0.3970371629542918" rpy="10.085414229613912 5.214353602771387 2.779195427006664"/>
	</joint>
	<joint name="939_to_837" type="revolute">
		<parent link="837"/>
		<child link="939"/>
		<axis xyz="1 0 0"/>
		<limit effort="1" lower="0" upper="1" velocity="1"/>
		<origin xyz="0.23720908794553752 0.048368111528088065 0.3970371629542918" rpy="15.128121344420869 5.214353602771387 2.779195427006664"/>
	</joint>
	<joint name="840_to_336" type="fixed">
		<parent link="336"/>
		<child link="840"/>
		<axis xyz="0 1 0"/>
		<limit effort="1" lower="0" upper="1" velocity="1"/>
		<origin xyz="0.9655793850913542 0.7355226604465349 0.9979723451106056" rpy="8.729781652921279 5.681016950828654 3.485998934322694"/>
	</joint>
	<joint name="941_to_840" type="revolute">
		<parent link="840"/>
		<child link="941"/>
		<axis xyz="1 0 0"/>
		<limit effort="1" lower="0" upper="1" velocity="1"/>
		<origin xyz="0.23720908794553752 0.048368111528088065 0.3970371629542918" rpy="10.085414229613912 5.214353602771387 2.779195427006664"/>
	</joint>
	<joint name="942_to_840" type="revolute">
		<parent link="840"/>
		<child link="942"/>
		<axis xyz="1 0 0"/>
		<limit effort="1" lower="0" upper="1" velocity="1"/>
		<origin xyz="0.23720908794553752 0.048368111528088065 0.3970371629542918" rpy="15.128121344420869 5.214353602771387 2.779195427006664"/>
	</joint>
	<joint name="343_to_228" type="revolute">
		<parent link="228"/>
		<child link="343"/>
		<axis xyz="1 0 0"/>
		<limit effort="1" lower="0" upper="1" velocity="1"/>
		<origin xyz="0.034789362477794517 0.8718791615597162 0.41043482191133807" rpy="19.612816612167848 3.944063460916242 1.10153216003229"/>
	</joint>
	<joint name="844_to_343" type="fixed">
		<parent link="343"/>
		<child link="844"/>
		<axis xyz="0 1 0"/>
		<limit effort="1" lower="0" upper="1" velocity="1"/>
		<origin xyz="0.9655793850913542 0.7355226604465349 0.9979723451106056" rpy="5.819854435280853 5.681016950828654 3.485998934322694"/>
	</joint>
	<joint name="945_to_844" type="revolute">
		<parent link="844"/>
		<child link="945"/>
		<axis xyz="1 0 0"/>
		<limit effort="1" lower="0" upper="1" velocity="1"/>
		<origin xyz="0.23720908794553752 0.048368111528088065 0.3970371629542918" rpy="10.085414229613912 5.214353602771387 2.779195427006664"/>
	</joint>
	<joint name="946_to_844" type="revolute">
		<parent link="844"/>
		<child link="946"/>
		<axis xyz="1 0 0"/>
		<limit effort="1" lower="0" upper="1" velocity="1"/>
		<origin xyz="0.23720908794553752 0.048368111528088065 0.3970371629542918" rpy="15.128121344420869 5.214353602771387 2.779195427006664"/>
	</joint>
	<joint name="847_to_343" type="fixed">
		<parent link="343"/>
		<child link="847"/>
		<axis xyz="0 1 0"/>
		<limit effort="1" lower="0" upper="1" velocity="1"/>
		<origin xyz="0.9655793850913542 0.7355226604465349 0.9979723451106056" rpy="8.729781652921279 5.681016950828654 3.485998934322694"/>
	</joint>
	<joint name="948_to_847" type="revolute">
		<parent link="847"/>
		<child link="948"/>
		<axis xyz="1 0 0"/>
		<limit effort="1" lower="0" upper="1" velocity="1"/>
		<origin xyz="0.23720908794553752 0.048368111528088065 0.3970371629542918" rpy="10.085414229613912 5.214353602771387 2.779195427006664"/>
	</joint>
	<joint name="949_to_847" type="revolute">
		<parent link="847"/>
		<child link="949"/>
		<axis xyz="1 0 0"/>
		<limit effort="1" lower="0" upper="1" velocity="1"/>
		<origin xyz="0.23720908794553752 0.048368111528088065 0.3970371629542918" rpy="15.128121344420869 5.214353602771387 2.779195427006664"/>
	</joint>
	<joint name="250_to_0" type="revolute">
		<parent link="0"/>
		<child link="250"/>
		<axis xyz="1 0 0"/>
		<limit effort="1" lower="0" upper="1" velocity="1"/>
		<origin xyz="0.3559143287974629 0.7831262154356912 0.884390288286699" rpy="13.452344883524587 5.329041761708994 4.499941867454197"/>
	</joint>
	<joint name="351_to_250" type="revolute">
		<parent link="250"/>
		<child link="351"/>
		<axis xyz="1 0 0"/>
		<limit effort="1" lower="0" upper="1" velocity="1"/>
		<origin xyz="0.034789362477794517 0.8718791615597162 0.41043482191133807" rpy="9.806408306083924 3.944063460916242 1.10153216003229"/>
	</joint>
	<joint name="852_to_351" type="fixed">
		<parent link="351"/>
		<child link="852"/>
		<axis xyz="0 1 0"/>
		<limit effort="1" lower="0" upper="1" velocity="1"/>
		<origin xyz="0.9655793850913542 0.7355226604465349 0.9979723451106056" rpy="5.819854435280853 5.681016950828654 3.485998934322694"/>
	</joint>
	<joint name="953_to_852" type="revolute">
		<parent link="852"/>
		<child link="953"/>
		<axis xyz="1 0 0"/>
		<limit effort="1" lower="0" upper="1" velocity="1"/>
		<origin xyz="0.23720908794553752 0.048368111528088065 0.3970371629542918" rpy="10.085414229613912 5.214353602771387 2.779195427006664"/>
	</joint>
	<joint name="954_to_852" type="revolute">
		<parent link="852"/>
		<child link="954"/>
		<axis xyz="1 0 0"/>
		<limit effort="1" lower="0" upper="1" velocity="1"/>
		<origin xyz="0.23720908794553752 0.048368111528088065 0.3970371629542918" rpy="15.128121344420869 5.214353602771387 2.779195427006664"/>
	</joint>
	<joint name="855_to_351" type="fixed">
		<parent link="351"/>
		<child link="855"/>
		<axis xyz="0 1 0"/>
		<limit effort="1" lower="0" upper="1" velocity="1"/>
		<origin xyz="0.9655793850913542 0.7355226604465349 0.9979723451106056" rpy="8.729781652921279 5.681016950828654 3.485998934322694"/>
	</joint>
	<joint name="956_to_855" type="revolute">
		<parent link="855"/>
		<child link="956"/>
		<axis xyz="1 0 0"/>
		<limit effort="1" lower="0" upper="1" velocity="1"/>
		<origin xyz="0.23720908794553752 0.048368111528088065 0.3970371629542918" rpy="10.085414229613912 5.214353602771387 2.779195427006664"/>
	</joint>
	<joint name="957_to_855" type="revolute">
		<parent link="855"/>
		<child link="957"/>
		<axis xyz="1 0 0"/>
		<limit effort="1" lower="0" upper="1" velocity="1"/>
		<origin xyz="0.23720908794553752 0.048368111528088065 0.3970371629542918" rpy="15.128121344420869 5.214353602771387 2.779195427006664"/>
	</joint>
	<joint name="358_to_250" type="revolute">
		<parent link="250"/>
		<child link="358"/>
		<axis xyz="1 0 0"/>
		<limit effort="1" lower="0" upper="1" velocity="1"/>
		<origin xyz="0.034789362477794517 0.8718791615597162 0.41043482191133807" rpy="14.709612459125886 3.944063460916242 1.10153216003229"/>
	</joint>
	<joint name="859_to_358" type="fixed">
		<parent link="358"/>
		<child link="859"/>
		<axis xyz="0 1 0"/>
		<limit effort="1" lower="0" upper="1" velocity="1"/>
		<origin xyz="0.9655793850913542 0.7355226604465349 0.9979723451106056" rpy="5.819854435280853 5.681016950828654 3.485998934322694"/>
	</joint>
	<joint name="960_to_859" type="revolute">
		<parent link="859"/>
		<child link="960"/>
		<axis xyz="1 0 0"/>
		<limit effort="1" lower="0" upper="1" velocity="1"/>
		<origin xyz="0.23720908794553752 0.048368111528088065 0.3970371629542918" rpy="10.085414229613912 5.214353602771387 2.779195427006664"/>
	</joint>
	<joint name="961_to_859" type="revolute">
		<parent link="859"/>
		<child link="961"/>
		<axis xyz="1 0 0"/>
		<limit effort="1" lower="0" upper="1" velocity="1"/>
		<origin xyz="0.23720908794553752 0.048368111528088065 0.3970371629542918" rpy="15.128121344420869 5.214353602771387 2.779195427006664"/>
	</joint>
	<joint name="862_to_358" type="fixed">
		<parent link="358"/>
		<child link="862"/>
		<axis xyz="0 1 0"/>
		<limit effort="1" lower="0" upper="1" velocity="1"/>
		<origin xyz="0.9655793850913542 0.7355226604465349 0.9979723451106056" rpy="8.729781652921279 5.681016950828654 3.485998934322694"/>
	</joint>
	<joint name="963_to_862" type="revolute">
		<parent link="862"/>
		<child link="963"/>
		<axis xyz="1 0 0"/>
		<limit effort="1" lower="0" upper="1" velocity="1"/>
		<origin xyz="0.23720908794553752 0.048368111528088065 0.3970371629542918" rpy="10.085414229613912 5.214353602771387 2.779195427006664"/>
	</joint>
	<joint name="964_to_862" type="revolute">
		<parent link="862"/>
		<child link="964"/>
		<axis xyz="1 0 0"/>
		<limit effort="1" lower="0" upper="1" velocity="1"/>
		<origin xyz="0.23720908794553752 0.048368111528088065 0.3970371629542918" rpy="15.128121344420869 5.214353602771387 2.779195427006664"/>
	</joint>
	<joint name="365_to_250" type="revolute">
		<parent link="250"/>
		<child link="365"/>
		<axis xyz="1 0 0"/>
		<limit effort="1" lower="0" upper="1" velocity="1"/>
		<origin xyz="0.034789362477794517 0.8718791615597162 0.41043482191133807" rpy="19.612816612167848 3.944063460916242 1.10153216003229"/>
	</joint>
	<joint name="866_to_365" type="fixed">
		<parent link="365"/>
		<child link="866"/>
		<axis xyz="0 1 0"/>
		<limit effort="1" lower="0" upper="1" velocity="1"/>
		<origin xyz="0.9655793850913542 0.7355226604465349 0.9979723451106056" rpy="5.819854435280853 5.681016950828654 3.485998934322694"/>
	</joint>
	<joint name="967_to_866" type="revolute">
		<parent link="866"/>
		<child link="967"/>
		<axis xyz="1 0 0"/>
		<limit effort="1" lower="0" upper="1" velocity="1"/>
		<origin xyz="0.23720908794553752 0.048368111528088065 0.3970371629542918" rpy="10.085414229613912 5.214353602771387 2.779195427006664"/>
	</joint>
	<joint name="968_to_866" type="revolute">
		<parent link="866"/>
		<child link="968"/>
		<axis xyz="1 0 0"/>
		<limit effort="1" lower="0" upper="1" velocity="1"/>
		<origin xyz="0.23720908794553752 0.048368111528088065 0.3970371629542918" rpy="15.128121344420869 5.214353602771387 2.779195427006664"/>
	</joint>
	<joint name="869_to_365" type="fixed">
		<parent link="365"/>
		<child link="869"/>
		<axis xyz="0 1 0"/>
		<limit effort="1" lower="0" upper="1" velocity="1"/>
		<origin xyz="0.9655793850913542 0.7355226604465349 0.9979723451106056" rpy="8.729781652921279 5.681016950828654 3.485998934322694"/>
	</joint>
	<joint name="970_to_869" type="revolute">
		<parent link="869"/>
		<child link="970"/>
		<axis xyz="1 0 0"/>
		<limit effort="1" lower="0" upper="1" velocity="1"/>
		<origin xyz="0.23720908794553752 0.048368111528088065 0.3970371629542918" rpy="10.085414229613912 5.214353602771387 2.779195427006664"/>
	</joint>
	<joint name="971_to_869" type="revolute">
		<parent link="869"/>
		<child link="971"/>
		<axis xyz="1 0 0"/>
		<limit effort="1" lower="0" upper="1" velocity="1"/>
		<origin xyz="0.23720908794553752 0.048368111528088065 0.3970371629542918" rpy="15.128121344420869 5.214353602771387 2.779195427006664"/>
	</joint>
	<joint name="472_to_0" type="fixed">
		<parent link="0"/>
		<child link="472"/>
		<axis xyz="0 1 0"/>
		<limit effort="1" lower="0" upper="1" velocity="1"/>
		<origin xyz="0.5556135273006634 0.21662018983104403 0.9799199721840421" rpy="33.20123874848164 5.125381263403724 5.872478919940978"/>
	</joint>
	<joint name="573_to_472" type="revolute">
		<parent link="472"/>
		<child link="573"/>
		<axis xyz="1 0 0"/>
		<limit effort="1" lower="0" upper="1" velocity="1"/>
		<origin xyz="0.014784523314157139 0.2702881838026293 0.41101139957404187" rpy="10.731034457319968 3.0878769621433055 1.2903560187182725"/>
	</joint>
	<joint name="774_to_472" type="fixed">
		<parent link="472"/>
		<child link="774"/>
		<axis xyz="0 1 0"/>
		<limit effort="1" lower="0" upper="1" velocity="1"/>
		<origin xyz="0.35349181017757325 0.2747036403798504 0.724753852086922" rpy="12.47643962005365 1.582210331733777 0.5357762635604469"/>
	</joint>
	<joint name="775_to_472" type="fixed">
		<parent link="472"/>
		<child link="775"/>
		<axis xyz="0 1 0"/>
		<limit effort="1" lower="0" upper="1" velocity="1"/>
		<origin xyz="0.35349181017757325 0.2747036403798504 0.724753852086922" rpy="16.6352528267382 1.582210331733777 0.5357762635604469"/>
	</joint>
	<joint name="776_to_472" type="fixed">
		<parent link="472"/>
		<child link="776"/>
		<axis xyz="0 1 0"/>
		<limit effort="1" lower="0" upper="1" velocity="1"/>
		<origin xyz="0.35349181017757325 0.2747036403798504 0.724753852086922" rpy="20.794066033422748 1.582210331733777 0.5357762635604469"/>
	</joint>
</robot>
