<robot name="creature">
	<link name="0">
		<visual>
			<geometry>
				<cylinder length="0.5573080881812439" radius="0.7670901600386566"/>
			</geometry>
		</visual>
		<collision>
			<geometry>
				<cylinder length="0.5573080881812439" radius="0.7670901600386566"/>
			</geometry>
		</collision>
		<inertial>
			<mass value="1.0302391330766618"/>
			<inertia ixx="0.03" iyy="0.03" izz="0.03" ixy="0" ixz="0" iyz="0"/>
		</inertial>
	</link>
	<link name="11">
		<visual>
			<geometry>
				<cylinder length="0.9571676671174556" radius="0.4400274755028324"/>
			</geometry>
		</visual>
		<collision>
			<geometry>
				<cylinder length="0.9571676671174556" radius="0.4400274755028324"/>
			</geometry>
		</collision>
		<inertial>
			<mass value="0.5822338920158273"/>
			<inertia ixx="0.03" iyy="0.03" izz="0.03" ixy="0" ixz="0" iyz="0"/>
		</inertial>
	</link>
	<link name="22">
		<visual>
			<geometry>
				<cylinder length="0.8946787194867123" radius="0.8702542881039664"/>
			</geometry>
		</visual>
		<collision>
			<geometry>
				<cylinder length="0.8946787194867123" radius="0.8702542881039664"/>
			</geometry>
		</collision>
		<inertial>
			<mass value="2.1286748252314216"/>
			<inertia ixx="0.03" iyy="0.03" izz="0.03" ixy="0" ixz="0" iyz="0"/>
		</inertial>
	</link>
	<joint name="11_to_0" type="fixed">
		<parent link="0"/>
		<child link="11"/>
		<axis xyz="0 1 0"/>
		<limit effort="1" lower="0" upper="1" velocity="1"/>
		<origin xyz="0.17653748874779107 0.3440860502999834 0.7451131631765382" rpy="9.867897497662396 5.159269839627949 0.7362513629478991"/>
	</joint>
	<joint name="22_to_11" type="revolute">
		<parent link="11"/>
		<child link="22"/>
		<axis xyz="1 0 0"/>
		<limit effort="1" lower="0" upper="1" velocity="1"/>
		<origin xyz="0.9147224362497208 0.5444887190374915 0.7300106873971209" rpy="8.92463800553296 3.1647728982054963 5.829585133325784"/>
	</joint>
</robot>
