<?xml version = "1.0"?>
<robot name="creature">
	<link name="0">
		<visual>
			<geometry>
				<cylinder length="0.6947566467451873" radius="0.4168303147205752"/>
			</geometry>
		</visual>
		<collision>
			<geometry>
				<cylinder length="0.6947566467451873" radius="0.4168303147205752"/>
			</geometry>
		</collision>
		<inertial>
			<mass value="0.379228681074032"/>
			<inertia ixx="0.03" iyy="0.03" izz="0.03" ixy="0" ixz="0" iyz="0"/>
		</inertial>
	</link>
	<link name="11">
		<visual>
			<geometry>
				<cylinder length="0.4163514564914441" radius="0.060649580600911634"/>
			</geometry>
		</visual>
		<collision>
			<geometry>
				<cylinder length="0.4163514564914441" radius="0.060649580600911634"/>
			</geometry>
		</collision>
		<inertial>
			<mass value="0.004811334648782012"/>
			<inertia ixx="0.03" iyy="0.03" izz="0.03" ixy="0" ixz="0" iyz="0"/>
		</inertial>
	</link>
	<link name="22">
		<visual>
			<geometry>
				<cylinder length="0.06394206520767987" radius="0.3019655027597512"/>
			</geometry>
		</visual>
		<collision>
			<geometry>
				<cylinder length="0.06394206520767987" radius="0.3019655027597512"/>
			</geometry>
		</collision>
		<inertial>
			<mass value="0.01831686707260863"/>
			<inertia ixx="0.03" iyy="0.03" izz="0.03" ixy="0" ixz="0" iyz="0"/>
		</inertial>
	</link>
	<link name="33">
		<visual>
			<geometry>
				<cylinder length="0.4607887728571125" radius="0.2785727017313713"/>
			</geometry>
		</visual>
		<collision>
			<geometry>
				<cylinder length="0.4607887728571125" radius="0.2785727017313713"/>
			</geometry>
		</collision>
		<inertial>
			<mass value="0.11233856554260431"/>
			<inertia ixx="0.03" iyy="0.03" izz="0.03" ixy="0" ixz="0" iyz="0"/>
		</inertial>
	</link>
	<link name="34">
		<visual>
			<geometry>
				<cylinder length="0.4607887728571125" radius="0.2785727017313713"/>
			</geometry>
		</visual>
		<collision>
			<geometry>
				<cylinder length="0.4607887728571125" radius="0.2785727017313713"/>
			</geometry>
		</collision>
		<inertial>
			<mass value="0.11233856554260431"/>
			<inertia ixx="0.03" iyy="0.03" izz="0.03" ixy="0" ixz="0" iyz="0"/>
		</inertial>
	</link>
	<link name="35">
		<visual>
			<geometry>
				<cylinder length="0.4607887728571125" radius="0.2785727017313713"/>
			</geometry>
		</visual>
		<collision>
			<geometry>
				<cylinder length="0.4607887728571125" radius="0.2785727017313713"/>
			</geometry>
		</collision>
		<inertial>
			<mass value="0.11233856554260431"/>
			<inertia ixx="0.03" iyy="0.03" izz="0.03" ixy="0" ixz="0" iyz="0"/>
		</inertial>
	</link>
	<link name="16">
		<visual>
			<geometry>
				<cylinder length="0.4163514564914441" radius="0.060649580600911634"/>
			</geometry>
		</visual>
		<collision>
			<geometry>
				<cylinder length="0.4163514564914441" radius="0.060649580600911634"/>
			</geometry>
		</collision>
		<inertial>
			<mass value="0.004811334648782012"/>
			<inertia ixx="0.03" iyy="0.03" izz="0.03" ixy="0" ixz="0" iyz="0"/>
		</inertial>
	</link>
	<link name="27">
		<visual>
			<geometry>
				<cylinder length="0.06394206520767987" radius="0.3019655027597512"/>
			</geometry>
		</visual>
		<collision>
			<geometry>
				<cylinder length="0.06394206520767987" radius="0.3019655027597512"/>
			</geometry>
		</collision>
		<inertial>
			<mass value="0.01831686707260863"/>
			<inertia ixx="0.03" iyy="0.03" izz="0.03" ixy="0" ixz="0" iyz="0"/>
		</inertial>
	</link>
	<link name="38">
		<visual>
			<geometry>
				<cylinder length="0.4607887728571125" radius="0.2785727017313713"/>
			</geometry>
		</visual>
		<collision>
			<geometry>
				<cylinder length="0.4607887728571125" radius="0.2785727017313713"/>
			</geometry>
		</collision>
		<inertial>
			<mass value="0.11233856554260431"/>
			<inertia ixx="0.03" iyy="0.03" izz="0.03" ixy="0" ixz="0" iyz="0"/>
		</inertial>
	</link>
	<link name="39">
		<visual>
			<geometry>
				<cylinder length="0.4607887728571125" radius="0.2785727017313713"/>
			</geometry>
		</visual>
		<collision>
			<geometry>
				<cylinder length="0.4607887728571125" radius="0.2785727017313713"/>
			</geometry>
		</collision>
		<inertial>
			<mass value="0.11233856554260431"/>
			<inertia ixx="0.03" iyy="0.03" izz="0.03" ixy="0" ixz="0" iyz="0"/>
		</inertial>
	</link>
	<link name="310">
		<visual>
			<geometry>
				<cylinder length="0.4607887728571125" radius="0.2785727017313713"/>
			</geometry>
		</visual>
		<collision>
			<geometry>
				<cylinder length="0.4607887728571125" radius="0.2785727017313713"/>
			</geometry>
		</collision>
		<inertial>
			<mass value="0.11233856554260431"/>
			<inertia ixx="0.03" iyy="0.03" izz="0.03" ixy="0" ixz="0" iyz="0"/>
		</inertial>
	</link>
	<link name="111">
		<visual>
			<geometry>
				<cylinder length="0.4163514564914441" radius="0.060649580600911634"/>
			</geometry>
		</visual>
		<collision>
			<geometry>
				<cylinder length="0.4163514564914441" radius="0.060649580600911634"/>
			</geometry>
		</collision>
		<inertial>
			<mass value="0.004811334648782012"/>
			<inertia ixx="0.03" iyy="0.03" izz="0.03" ixy="0" ixz="0" iyz="0"/>
		</inertial>
	</link>
	<link name="212">
		<visual>
			<geometry>
				<cylinder length="0.06394206520767987" radius="0.3019655027597512"/>
			</geometry>
		</visual>
		<collision>
			<geometry>
				<cylinder length="0.06394206520767987" radius="0.3019655027597512"/>
			</geometry>
		</collision>
		<inertial>
			<mass value="0.01831686707260863"/>
			<inertia ixx="0.03" iyy="0.03" izz="0.03" ixy="0" ixz="0" iyz="0"/>
		</inertial>
	</link>
	<link name="313">
		<visual>
			<geometry>
				<cylinder length="0.4607887728571125" radius="0.2785727017313713"/>
			</geometry>
		</visual>
		<collision>
			<geometry>
				<cylinder length="0.4607887728571125" radius="0.2785727017313713"/>
			</geometry>
		</collision>
		<inertial>
			<mass value="0.11233856554260431"/>
			<inertia ixx="0.03" iyy="0.03" izz="0.03" ixy="0" ixz="0" iyz="0"/>
		</inertial>
	</link>
	<link name="314">
		<visual>
			<geometry>
				<cylinder length="0.4607887728571125" radius="0.2785727017313713"/>
			</geometry>
		</visual>
		<collision>
			<geometry>
				<cylinder length="0.4607887728571125" radius="0.2785727017313713"/>
			</geometry>
		</collision>
		<inertial>
			<mass value="0.11233856554260431"/>
			<inertia ixx="0.03" iyy="0.03" izz="0.03" ixy="0" ixz="0" iyz="0"/>
		</inertial>
	</link>
	<link name="315">
		<visual>
			<geometry>
				<cylinder length="0.4607887728571125" radius="0.2785727017313713"/>
			</geometry>
		</visual>
		<collision>
			<geometry>
				<cylinder length="0.4607887728571125" radius="0.2785727017313713"/>
			</geometry>
		</collision>
		<inertial>
			<mass value="0.11233856554260431"/>
			<inertia ixx="0.03" iyy="0.03" izz="0.03" ixy="0" ixz="0" iyz="0"/>
		</inertial>
	</link>
	<joint name="11_to_0" type="revolute">
		<parent link="0"/>
		<child link="11"/>
		<axis xyz="0 1 0"/>
		<limit effort="1" lower="0" upper="1" velocity="1"/>
		<origin xyz="0.9473825943233579 0.9666966049542175 0.823210706693203" rpy="12.038899064003731 1.9010852332557484 0.5773673394753234"/>
	</joint>
	<joint name="22_to_11" type="fixed">
		<parent link="11"/>
		<child link="22"/>
		<axis xyz="0 0 1"/>
		<limit effort="1" lower="0" upper="1" velocity="1"/>
		<origin xyz="0.8779586040207958 0.499244388831796 0.9494901677698329" rpy="5.101765924389607 2.9320033657587414 5.966787281651236"/>
	</joint>
	<joint name="33_to_22" type="fixed">
		<parent link="22"/>
		<child link="33"/>
		<axis xyz="0 1 0"/>
		<limit effort="1" lower="0" upper="1" velocity="1"/>
		<origin xyz="0.5504635630457306 0.3983319839263335 0.5626102165821691" rpy="6.103235118657083 0.2749492954396795 0.6965639065044237"/>
	</joint>
	<joint name="34_to_22" type="fixed">
		<parent link="22"/>
		<child link="34"/>
		<axis xyz="0 1 0"/>
		<limit effort="1" lower="0" upper="1" velocity="1"/>
		<origin xyz="0.5504635630457306 0.3983319839263335 0.5626102165821691" rpy="9.154852677985625 0.2749492954396795 0.6965639065044237"/>
	</joint>
	<joint name="35_to_22" type="fixed">
		<parent link="22"/>
		<child link="35"/>
		<axis xyz="0 1 0"/>
		<limit effort="1" lower="0" upper="1" velocity="1"/>
		<origin xyz="0.5504635630457306 0.3983319839263335 0.5626102165821691" rpy="12.206470237314166 0.2749492954396795 0.6965639065044237"/>
	</joint>
	<joint name="16_to_0" type="revolute">
		<parent link="0"/>
		<child link="16"/>
		<axis xyz="0 1 0"/>
		<limit effort="1" lower="0" upper="1" velocity="1"/>
		<origin xyz="0.9473825943233579 0.9666966049542175 0.823210706693203" rpy="18.058348596005597 1.9010852332557484 0.5773673394753234"/>
	</joint>
	<joint name="27_to_16" type="fixed">
		<parent link="16"/>
		<child link="27"/>
		<axis xyz="0 0 1"/>
		<limit effort="1" lower="0" upper="1" velocity="1"/>
		<origin xyz="0.8779586040207958 0.499244388831796 0.9494901677698329" rpy="5.101765924389607 2.9320033657587414 5.966787281651236"/>
	</joint>
	<joint name="38_to_27" type="fixed">
		<parent link="27"/>
		<child link="38"/>
		<axis xyz="0 1 0"/>
		<limit effort="1" lower="0" upper="1" velocity="1"/>
		<origin xyz="0.5504635630457306 0.3983319839263335 0.5626102165821691" rpy="6.103235118657083 0.2749492954396795 0.6965639065044237"/>
	</joint>
	<joint name="39_to_27" type="fixed">
		<parent link="27"/>
		<child link="39"/>
		<axis xyz="0 1 0"/>
		<limit effort="1" lower="0" upper="1" velocity="1"/>
		<origin xyz="0.5504635630457306 0.3983319839263335 0.5626102165821691" rpy="9.154852677985625 0.2749492954396795 0.6965639065044237"/>
	</joint>
	<joint name="310_to_27" type="fixed">
		<parent link="27"/>
		<child link="310"/>
		<axis xyz="0 1 0"/>
		<limit effort="1" lower="0" upper="1" velocity="1"/>
		<origin xyz="0.5504635630457306 0.3983319839263335 0.5626102165821691" rpy="12.206470237314166 0.2749492954396795 0.6965639065044237"/>
	</joint>
	<joint name="111_to_0" type="revolute">
		<parent link="0"/>
		<child link="111"/>
		<axis xyz="0 1 0"/>
		<limit effort="1" lower="0" upper="1" velocity="1"/>
		<origin xyz="0.9473825943233579 0.9666966049542175 0.823210706693203" rpy="24.077798128007462 1.9010852332557484 0.5773673394753234"/>
	</joint>
	<joint name="212_to_111" type="fixed">
		<parent link="111"/>
		<child link="212"/>
		<axis xyz="0 0 1"/>
		<limit effort="1" lower="0" upper="1" velocity="1"/>
		<origin xyz="0.8779586040207958 0.499244388831796 0.9494901677698329" rpy="5.101765924389607 2.9320033657587414 5.966787281651236"/>
	</joint>
	<joint name="313_to_212" type="fixed">
		<parent link="212"/>
		<child link="313"/>
		<axis xyz="0 1 0"/>
		<limit effort="1" lower="0" upper="1" velocity="1"/>
		<origin xyz="0.5504635630457306 0.3983319839263335 0.5626102165821691" rpy="6.103235118657083 0.2749492954396795 0.6965639065044237"/>
	</joint>
	<joint name="314_to_212" type="fixed">
		<parent link="212"/>
		<child link="314"/>
		<axis xyz="0 1 0"/>
		<limit effort="1" lower="0" upper="1" velocity="1"/>
		<origin xyz="0.5504635630457306 0.3983319839263335 0.5626102165821691" rpy="9.154852677985625 0.2749492954396795 0.6965639065044237"/>
	</joint>
	<joint name="315_to_212" type="fixed">
		<parent link="212"/>
		<child link="315"/>
		<axis xyz="0 1 0"/>
		<limit effort="1" lower="0" upper="1" velocity="1"/>
		<origin xyz="0.5504635630457306 0.3983319839263335 0.5626102165821691" rpy="12.206470237314166 0.2749492954396795 0.6965639065044237"/>
	</joint>
</robot>
