<?xml version = "1.0"?>
<robot name="creature">
	<link name="0">
		<visual>
			<geometry>
				<cylinder length="-0.07585149201268016" radius="0.8118105645304132"/>
			</geometry>
		</visual>
		<collision>
			<geometry>
				<cylinder length="-0.07585149201268016" radius="0.8118105645304132"/>
			</geometry>
		</collision>
		<inertial>
			<mass value="-0.15704474113257996"/>
			<inertia ixx="0.03" iyy="0.03" izz="0.03" ixy="0" ixz="0" iyz="0"/>
		</inertial>
	</link>
	<link name="11">
		<visual>
			<geometry>
				<cylinder length="0.5580677922099168" radius="0.3541920880394521"/>
			</geometry>
		</visual>
		<collision>
			<geometry>
				<cylinder length="0.5580677922099168" radius="0.3541920880394521"/>
			</geometry>
		</collision>
		<inertial>
			<mass value="0.21994522748967252"/>
			<inertia ixx="0.03" iyy="0.03" izz="0.03" ixy="0" ixz="0" iyz="0"/>
		</inertial>
	</link>
	<link name="12">
		<visual>
			<geometry>
				<cylinder length="0.5580677922099168" radius="0.3541920880394521"/>
			</geometry>
		</visual>
		<collision>
			<geometry>
				<cylinder length="0.5580677922099168" radius="0.3541920880394521"/>
			</geometry>
		</collision>
		<inertial>
			<mass value="0.21994522748967252"/>
			<inertia ixx="0.03" iyy="0.03" izz="0.03" ixy="0" ixz="0" iyz="0"/>
		</inertial>
	</link>
	<link name="13">
		<visual>
			<geometry>
				<cylinder length="0.5580677922099168" radius="0.3541920880394521"/>
			</geometry>
		</visual>
		<collision>
			<geometry>
				<cylinder length="0.5580677922099168" radius="0.3541920880394521"/>
			</geometry>
		</collision>
		<inertial>
			<mass value="0.21994522748967252"/>
			<inertia ixx="0.03" iyy="0.03" izz="0.03" ixy="0" ixz="0" iyz="0"/>
		</inertial>
	</link>
	<link name="24">
		<visual>
			<geometry>
				<cylinder length="0.2766491856282819" radius="0.5107725720542728"/>
			</geometry>
		</visual>
		<collision>
			<geometry>
				<cylinder length="0.2766491856282819" radius="0.5107725720542728"/>
			</geometry>
		</collision>
		<inertial>
			<mass value="0.22674326967469466"/>
			<inertia ixx="0.03" iyy="0.03" izz="0.03" ixy="0" ixz="0" iyz="0"/>
		</inertial>
	</link>
	<link name="25">
		<visual>
			<geometry>
				<cylinder length="0.2766491856282819" radius="0.5107725720542728"/>
			</geometry>
		</visual>
		<collision>
			<geometry>
				<cylinder length="0.2766491856282819" radius="0.5107725720542728"/>
			</geometry>
		</collision>
		<inertial>
			<mass value="0.22674326967469466"/>
			<inertia ixx="0.03" iyy="0.03" izz="0.03" ixy="0" ixz="0" iyz="0"/>
		</inertial>
	</link>
	<link name="26">
		<visual>
			<geometry>
				<cylinder length="0.2766491856282819" radius="0.5107725720542728"/>
			</geometry>
		</visual>
		<collision>
			<geometry>
				<cylinder length="0.2766491856282819" radius="0.5107725720542728"/>
			</geometry>
		</collision>
		<inertial>
			<mass value="0.22674326967469466"/>
			<inertia ixx="0.03" iyy="0.03" izz="0.03" ixy="0" ixz="0" iyz="0"/>
		</inertial>
	</link>
	<link name="27">
		<visual>
			<geometry>
				<cylinder length="0.2766491856282819" radius="0.5107725720542728"/>
			</geometry>
		</visual>
		<collision>
			<geometry>
				<cylinder length="0.2766491856282819" radius="0.5107725720542728"/>
			</geometry>
		</collision>
		<inertial>
			<mass value="0.22674326967469466"/>
			<inertia ixx="0.03" iyy="0.03" izz="0.03" ixy="0" ixz="0" iyz="0"/>
		</inertial>
	</link>
	<link name="28">
		<visual>
			<geometry>
				<cylinder length="0.2766491856282819" radius="0.5107725720542728"/>
			</geometry>
		</visual>
		<collision>
			<geometry>
				<cylinder length="0.2766491856282819" radius="0.5107725720542728"/>
			</geometry>
		</collision>
		<inertial>
			<mass value="0.22674326967469466"/>
			<inertia ixx="0.03" iyy="0.03" izz="0.03" ixy="0" ixz="0" iyz="0"/>
		</inertial>
	</link>
	<link name="39">
		<visual>
			<geometry>
				<cylinder length="0.2766491856282819" radius="0.5107725720542728"/>
			</geometry>
		</visual>
		<collision>
			<geometry>
				<cylinder length="0.2766491856282819" radius="0.5107725720542728"/>
			</geometry>
		</collision>
		<inertial>
			<mass value="0.22674326967469466"/>
			<inertia ixx="0.03" iyy="0.03" izz="0.03" ixy="0" ixz="0" iyz="0"/>
		</inertial>
	</link>
	<link name="410">
		<visual>
			<geometry>
				<cylinder length="0.7673767897591459" radius="0.4813982728319718"/>
			</geometry>
		</visual>
		<collision>
			<geometry>
				<cylinder length="0.7673767897591459" radius="0.4813982728319718"/>
			</geometry>
		</collision>
		<inertial>
			<mass value="0.5586857413528794"/>
			<inertia ixx="0.03" iyy="0.03" izz="0.03" ixy="0" ixz="0" iyz="0"/>
		</inertial>
	</link>
	<link name="611">
		<visual>
			<geometry>
				<cylinder length="0.841385341207147" radius="0.041099466365797754"/>
			</geometry>
		</visual>
		<collision>
			<geometry>
				<cylinder length="0.841385341207147" radius="0.041099466365797754"/>
			</geometry>
		</collision>
		<inertial>
			<mass value="0.004464955965890071"/>
			<inertia ixx="0.03" iyy="0.03" izz="0.03" ixy="0" ixz="0" iyz="0"/>
		</inertial>
	</link>
	<link name="412">
		<visual>
			<geometry>
				<cylinder length="0.7673767897591459" radius="0.4813982728319718"/>
			</geometry>
		</visual>
		<collision>
			<geometry>
				<cylinder length="0.7673767897591459" radius="0.4813982728319718"/>
			</geometry>
		</collision>
		<inertial>
			<mass value="0.5586857413528794"/>
			<inertia ixx="0.03" iyy="0.03" izz="0.03" ixy="0" ixz="0" iyz="0"/>
		</inertial>
	</link>
	<link name="613">
		<visual>
			<geometry>
				<cylinder length="0.841385341207147" radius="0.041099466365797754"/>
			</geometry>
		</visual>
		<collision>
			<geometry>
				<cylinder length="0.841385341207147" radius="0.041099466365797754"/>
			</geometry>
		</collision>
		<inertial>
			<mass value="0.004464955965890071"/>
			<inertia ixx="0.03" iyy="0.03" izz="0.03" ixy="0" ixz="0" iyz="0"/>
		</inertial>
	</link>
	<link name="514">
		<visual>
			<geometry>
				<cylinder length="1.0447548931131596" radius="0.8348491283863317"/>
			</geometry>
		</visual>
		<collision>
			<geometry>
				<cylinder length="1.0447548931131596" radius="0.8348491283863317"/>
			</geometry>
		</collision>
		<inertial>
			<mass value="2.2876010262238817"/>
			<inertia ixx="0.03" iyy="0.03" izz="0.03" ixy="0" ixz="0" iyz="0"/>
		</inertial>
	</link>
	<link name="715">
		<visual>
			<geometry>
				<cylinder length="1.6010658238443112" radius="0.8546907703575893"/>
			</geometry>
		</visual>
		<collision>
			<geometry>
				<cylinder length="1.6010658238443112" radius="0.8546907703575893"/>
			</geometry>
		</collision>
		<inertial>
			<mass value="3.6743209427316383"/>
			<inertia ixx="0.03" iyy="0.03" izz="0.03" ixy="0" ixz="0" iyz="0"/>
		</inertial>
	</link>
	<link name="716">
		<visual>
			<geometry>
				<cylinder length="1.6010658238443112" radius="0.8546907703575893"/>
			</geometry>
		</visual>
		<collision>
			<geometry>
				<cylinder length="1.6010658238443112" radius="0.8546907703575893"/>
			</geometry>
		</collision>
		<inertial>
			<mass value="3.6743209427316383"/>
			<inertia ixx="0.03" iyy="0.03" izz="0.03" ixy="0" ixz="0" iyz="0"/>
		</inertial>
	</link>
	<link name="717">
		<visual>
			<geometry>
				<cylinder length="1.6010658238443112" radius="0.8546907703575893"/>
			</geometry>
		</visual>
		<collision>
			<geometry>
				<cylinder length="1.6010658238443112" radius="0.8546907703575893"/>
			</geometry>
		</collision>
		<inertial>
			<mass value="3.6743209427316383"/>
			<inertia ixx="0.03" iyy="0.03" izz="0.03" ixy="0" ixz="0" iyz="0"/>
		</inertial>
	</link>
	<link name="718">
		<visual>
			<geometry>
				<cylinder length="1.6010658238443112" radius="0.8546907703575893"/>
			</geometry>
		</visual>
		<collision>
			<geometry>
				<cylinder length="1.6010658238443112" radius="0.8546907703575893"/>
			</geometry>
		</collision>
		<inertial>
			<mass value="3.6743209427316383"/>
			<inertia ixx="0.03" iyy="0.03" izz="0.03" ixy="0" ixz="0" iyz="0"/>
		</inertial>
	</link>
	<link name="519">
		<visual>
			<geometry>
				<cylinder length="1.0447548931131596" radius="0.8348491283863317"/>
			</geometry>
		</visual>
		<collision>
			<geometry>
				<cylinder length="1.0447548931131596" radius="0.8348491283863317"/>
			</geometry>
		</collision>
		<inertial>
			<mass value="2.2876010262238817"/>
			<inertia ixx="0.03" iyy="0.03" izz="0.03" ixy="0" ixz="0" iyz="0"/>
		</inertial>
	</link>
	<link name="720">
		<visual>
			<geometry>
				<cylinder length="1.6010658238443112" radius="0.8546907703575893"/>
			</geometry>
		</visual>
		<collision>
			<geometry>
				<cylinder length="1.6010658238443112" radius="0.8546907703575893"/>
			</geometry>
		</collision>
		<inertial>
			<mass value="3.6743209427316383"/>
			<inertia ixx="0.03" iyy="0.03" izz="0.03" ixy="0" ixz="0" iyz="0"/>
		</inertial>
	</link>
	<link name="721">
		<visual>
			<geometry>
				<cylinder length="1.6010658238443112" radius="0.8546907703575893"/>
			</geometry>
		</visual>
		<collision>
			<geometry>
				<cylinder length="1.6010658238443112" radius="0.8546907703575893"/>
			</geometry>
		</collision>
		<inertial>
			<mass value="3.6743209427316383"/>
			<inertia ixx="0.03" iyy="0.03" izz="0.03" ixy="0" ixz="0" iyz="0"/>
		</inertial>
	</link>
	<link name="722">
		<visual>
			<geometry>
				<cylinder length="1.6010658238443112" radius="0.8546907703575893"/>
			</geometry>
		</visual>
		<collision>
			<geometry>
				<cylinder length="1.6010658238443112" radius="0.8546907703575893"/>
			</geometry>
		</collision>
		<inertial>
			<mass value="3.6743209427316383"/>
			<inertia ixx="0.03" iyy="0.03" izz="0.03" ixy="0" ixz="0" iyz="0"/>
		</inertial>
	</link>
	<link name="723">
		<visual>
			<geometry>
				<cylinder length="1.6010658238443112" radius="0.8546907703575893"/>
			</geometry>
		</visual>
		<collision>
			<geometry>
				<cylinder length="1.6010658238443112" radius="0.8546907703575893"/>
			</geometry>
		</collision>
		<inertial>
			<mass value="3.6743209427316383"/>
			<inertia ixx="0.03" iyy="0.03" izz="0.03" ixy="0" ixz="0" iyz="0"/>
		</inertial>
	</link>
	<link name="324">
		<visual>
			<geometry>
				<cylinder length="0.2766491856282819" radius="0.5107725720542728"/>
			</geometry>
		</visual>
		<collision>
			<geometry>
				<cylinder length="0.2766491856282819" radius="0.5107725720542728"/>
			</geometry>
		</collision>
		<inertial>
			<mass value="0.22674326967469466"/>
			<inertia ixx="0.03" iyy="0.03" izz="0.03" ixy="0" ixz="0" iyz="0"/>
		</inertial>
	</link>
	<link name="425">
		<visual>
			<geometry>
				<cylinder length="0.7673767897591459" radius="0.4813982728319718"/>
			</geometry>
		</visual>
		<collision>
			<geometry>
				<cylinder length="0.7673767897591459" radius="0.4813982728319718"/>
			</geometry>
		</collision>
		<inertial>
			<mass value="0.5586857413528794"/>
			<inertia ixx="0.03" iyy="0.03" izz="0.03" ixy="0" ixz="0" iyz="0"/>
		</inertial>
	</link>
	<link name="626">
		<visual>
			<geometry>
				<cylinder length="0.841385341207147" radius="0.041099466365797754"/>
			</geometry>
		</visual>
		<collision>
			<geometry>
				<cylinder length="0.841385341207147" radius="0.041099466365797754"/>
			</geometry>
		</collision>
		<inertial>
			<mass value="0.004464955965890071"/>
			<inertia ixx="0.03" iyy="0.03" izz="0.03" ixy="0" ixz="0" iyz="0"/>
		</inertial>
	</link>
	<link name="427">
		<visual>
			<geometry>
				<cylinder length="0.7673767897591459" radius="0.4813982728319718"/>
			</geometry>
		</visual>
		<collision>
			<geometry>
				<cylinder length="0.7673767897591459" radius="0.4813982728319718"/>
			</geometry>
		</collision>
		<inertial>
			<mass value="0.5586857413528794"/>
			<inertia ixx="0.03" iyy="0.03" izz="0.03" ixy="0" ixz="0" iyz="0"/>
		</inertial>
	</link>
	<link name="628">
		<visual>
			<geometry>
				<cylinder length="0.841385341207147" radius="0.041099466365797754"/>
			</geometry>
		</visual>
		<collision>
			<geometry>
				<cylinder length="0.841385341207147" radius="0.041099466365797754"/>
			</geometry>
		</collision>
		<inertial>
			<mass value="0.004464955965890071"/>
			<inertia ixx="0.03" iyy="0.03" izz="0.03" ixy="0" ixz="0" iyz="0"/>
		</inertial>
	</link>
	<link name="529">
		<visual>
			<geometry>
				<cylinder length="1.0447548931131596" radius="0.8348491283863317"/>
			</geometry>
		</visual>
		<collision>
			<geometry>
				<cylinder length="1.0447548931131596" radius="0.8348491283863317"/>
			</geometry>
		</collision>
		<inertial>
			<mass value="2.2876010262238817"/>
			<inertia ixx="0.03" iyy="0.03" izz="0.03" ixy="0" ixz="0" iyz="0"/>
		</inertial>
	</link>
	<link name="730">
		<visual>
			<geometry>
				<cylinder length="1.6010658238443112" radius="0.8546907703575893"/>
			</geometry>
		</visual>
		<collision>
			<geometry>
				<cylinder length="1.6010658238443112" radius="0.8546907703575893"/>
			</geometry>
		</collision>
		<inertial>
			<mass value="3.6743209427316383"/>
			<inertia ixx="0.03" iyy="0.03" izz="0.03" ixy="0" ixz="0" iyz="0"/>
		</inertial>
	</link>
	<link name="731">
		<visual>
			<geometry>
				<cylinder length="1.6010658238443112" radius="0.8546907703575893"/>
			</geometry>
		</visual>
		<collision>
			<geometry>
				<cylinder length="1.6010658238443112" radius="0.8546907703575893"/>
			</geometry>
		</collision>
		<inertial>
			<mass value="3.6743209427316383"/>
			<inertia ixx="0.03" iyy="0.03" izz="0.03" ixy="0" ixz="0" iyz="0"/>
		</inertial>
	</link>
	<link name="732">
		<visual>
			<geometry>
				<cylinder length="1.6010658238443112" radius="0.8546907703575893"/>
			</geometry>
		</visual>
		<collision>
			<geometry>
				<cylinder length="1.6010658238443112" radius="0.8546907703575893"/>
			</geometry>
		</collision>
		<inertial>
			<mass value="3.6743209427316383"/>
			<inertia ixx="0.03" iyy="0.03" izz="0.03" ixy="0" ixz="0" iyz="0"/>
		</inertial>
	</link>
	<link name="733">
		<visual>
			<geometry>
				<cylinder length="1.6010658238443112" radius="0.8546907703575893"/>
			</geometry>
		</visual>
		<collision>
			<geometry>
				<cylinder length="1.6010658238443112" radius="0.8546907703575893"/>
			</geometry>
		</collision>
		<inertial>
			<mass value="3.6743209427316383"/>
			<inertia ixx="0.03" iyy="0.03" izz="0.03" ixy="0" ixz="0" iyz="0"/>
		</inertial>
	</link>
	<link name="534">
		<visual>
			<geometry>
				<cylinder length="1.0447548931131596" radius="0.8348491283863317"/>
			</geometry>
		</visual>
		<collision>
			<geometry>
				<cylinder length="1.0447548931131596" radius="0.8348491283863317"/>
			</geometry>
		</collision>
		<inertial>
			<mass value="2.2876010262238817"/>
			<inertia ixx="0.03" iyy="0.03" izz="0.03" ixy="0" ixz="0" iyz="0"/>
		</inertial>
	</link>
	<link name="735">
		<visual>
			<geometry>
				<cylinder length="1.6010658238443112" radius="0.8546907703575893"/>
			</geometry>
		</visual>
		<collision>
			<geometry>
				<cylinder length="1.6010658238443112" radius="0.8546907703575893"/>
			</geometry>
		</collision>
		<inertial>
			<mass value="3.6743209427316383"/>
			<inertia ixx="0.03" iyy="0.03" izz="0.03" ixy="0" ixz="0" iyz="0"/>
		</inertial>
	</link>
	<link name="736">
		<visual>
			<geometry>
				<cylinder length="1.6010658238443112" radius="0.8546907703575893"/>
			</geometry>
		</visual>
		<collision>
			<geometry>
				<cylinder length="1.6010658238443112" radius="0.8546907703575893"/>
			</geometry>
		</collision>
		<inertial>
			<mass value="3.6743209427316383"/>
			<inertia ixx="0.03" iyy="0.03" izz="0.03" ixy="0" ixz="0" iyz="0"/>
		</inertial>
	</link>
	<link name="737">
		<visual>
			<geometry>
				<cylinder length="1.6010658238443112" radius="0.8546907703575893"/>
			</geometry>
		</visual>
		<collision>
			<geometry>
				<cylinder length="1.6010658238443112" radius="0.8546907703575893"/>
			</geometry>
		</collision>
		<inertial>
			<mass value="3.6743209427316383"/>
			<inertia ixx="0.03" iyy="0.03" izz="0.03" ixy="0" ixz="0" iyz="0"/>
		</inertial>
	</link>
	<link name="738">
		<visual>
			<geometry>
				<cylinder length="1.6010658238443112" radius="0.8546907703575893"/>
			</geometry>
		</visual>
		<collision>
			<geometry>
				<cylinder length="1.6010658238443112" radius="0.8546907703575893"/>
			</geometry>
		</collision>
		<inertial>
			<mass value="3.6743209427316383"/>
			<inertia ixx="0.03" iyy="0.03" izz="0.03" ixy="0" ixz="0" iyz="0"/>
		</inertial>
	</link>
	<link name="339">
		<visual>
			<geometry>
				<cylinder length="0.2766491856282819" radius="0.5107725720542728"/>
			</geometry>
		</visual>
		<collision>
			<geometry>
				<cylinder length="0.2766491856282819" radius="0.5107725720542728"/>
			</geometry>
		</collision>
		<inertial>
			<mass value="0.22674326967469466"/>
			<inertia ixx="0.03" iyy="0.03" izz="0.03" ixy="0" ixz="0" iyz="0"/>
		</inertial>
	</link>
	<link name="440">
		<visual>
			<geometry>
				<cylinder length="0.7673767897591459" radius="0.4813982728319718"/>
			</geometry>
		</visual>
		<collision>
			<geometry>
				<cylinder length="0.7673767897591459" radius="0.4813982728319718"/>
			</geometry>
		</collision>
		<inertial>
			<mass value="0.5586857413528794"/>
			<inertia ixx="0.03" iyy="0.03" izz="0.03" ixy="0" ixz="0" iyz="0"/>
		</inertial>
	</link>
	<link name="641">
		<visual>
			<geometry>
				<cylinder length="0.841385341207147" radius="0.041099466365797754"/>
			</geometry>
		</visual>
		<collision>
			<geometry>
				<cylinder length="0.841385341207147" radius="0.041099466365797754"/>
			</geometry>
		</collision>
		<inertial>
			<mass value="0.004464955965890071"/>
			<inertia ixx="0.03" iyy="0.03" izz="0.03" ixy="0" ixz="0" iyz="0"/>
		</inertial>
	</link>
	<link name="442">
		<visual>
			<geometry>
				<cylinder length="0.7673767897591459" radius="0.4813982728319718"/>
			</geometry>
		</visual>
		<collision>
			<geometry>
				<cylinder length="0.7673767897591459" radius="0.4813982728319718"/>
			</geometry>
		</collision>
		<inertial>
			<mass value="0.5586857413528794"/>
			<inertia ixx="0.03" iyy="0.03" izz="0.03" ixy="0" ixz="0" iyz="0"/>
		</inertial>
	</link>
	<link name="643">
		<visual>
			<geometry>
				<cylinder length="0.841385341207147" radius="0.041099466365797754"/>
			</geometry>
		</visual>
		<collision>
			<geometry>
				<cylinder length="0.841385341207147" radius="0.041099466365797754"/>
			</geometry>
		</collision>
		<inertial>
			<mass value="0.004464955965890071"/>
			<inertia ixx="0.03" iyy="0.03" izz="0.03" ixy="0" ixz="0" iyz="0"/>
		</inertial>
	</link>
	<link name="544">
		<visual>
			<geometry>
				<cylinder length="1.0447548931131596" radius="0.8348491283863317"/>
			</geometry>
		</visual>
		<collision>
			<geometry>
				<cylinder length="1.0447548931131596" radius="0.8348491283863317"/>
			</geometry>
		</collision>
		<inertial>
			<mass value="2.2876010262238817"/>
			<inertia ixx="0.03" iyy="0.03" izz="0.03" ixy="0" ixz="0" iyz="0"/>
		</inertial>
	</link>
	<link name="745">
		<visual>
			<geometry>
				<cylinder length="1.6010658238443112" radius="0.8546907703575893"/>
			</geometry>
		</visual>
		<collision>
			<geometry>
				<cylinder length="1.6010658238443112" radius="0.8546907703575893"/>
			</geometry>
		</collision>
		<inertial>
			<mass value="3.6743209427316383"/>
			<inertia ixx="0.03" iyy="0.03" izz="0.03" ixy="0" ixz="0" iyz="0"/>
		</inertial>
	</link>
	<link name="746">
		<visual>
			<geometry>
				<cylinder length="1.6010658238443112" radius="0.8546907703575893"/>
			</geometry>
		</visual>
		<collision>
			<geometry>
				<cylinder length="1.6010658238443112" radius="0.8546907703575893"/>
			</geometry>
		</collision>
		<inertial>
			<mass value="3.6743209427316383"/>
			<inertia ixx="0.03" iyy="0.03" izz="0.03" ixy="0" ixz="0" iyz="0"/>
		</inertial>
	</link>
	<link name="747">
		<visual>
			<geometry>
				<cylinder length="1.6010658238443112" radius="0.8546907703575893"/>
			</geometry>
		</visual>
		<collision>
			<geometry>
				<cylinder length="1.6010658238443112" radius="0.8546907703575893"/>
			</geometry>
		</collision>
		<inertial>
			<mass value="3.6743209427316383"/>
			<inertia ixx="0.03" iyy="0.03" izz="0.03" ixy="0" ixz="0" iyz="0"/>
		</inertial>
	</link>
	<link name="748">
		<visual>
			<geometry>
				<cylinder length="1.6010658238443112" radius="0.8546907703575893"/>
			</geometry>
		</visual>
		<collision>
			<geometry>
				<cylinder length="1.6010658238443112" radius="0.8546907703575893"/>
			</geometry>
		</collision>
		<inertial>
			<mass value="3.6743209427316383"/>
			<inertia ixx="0.03" iyy="0.03" izz="0.03" ixy="0" ixz="0" iyz="0"/>
		</inertial>
	</link>
	<link name="549">
		<visual>
			<geometry>
				<cylinder length="1.0447548931131596" radius="0.8348491283863317"/>
			</geometry>
		</visual>
		<collision>
			<geometry>
				<cylinder length="1.0447548931131596" radius="0.8348491283863317"/>
			</geometry>
		</collision>
		<inertial>
			<mass value="2.2876010262238817"/>
			<inertia ixx="0.03" iyy="0.03" izz="0.03" ixy="0" ixz="0" iyz="0"/>
		</inertial>
	</link>
	<link name="750">
		<visual>
			<geometry>
				<cylinder length="1.6010658238443112" radius="0.8546907703575893"/>
			</geometry>
		</visual>
		<collision>
			<geometry>
				<cylinder length="1.6010658238443112" radius="0.8546907703575893"/>
			</geometry>
		</collision>
		<inertial>
			<mass value="3.6743209427316383"/>
			<inertia ixx="0.03" iyy="0.03" izz="0.03" ixy="0" ixz="0" iyz="0"/>
		</inertial>
	</link>
	<link name="751">
		<visual>
			<geometry>
				<cylinder length="1.6010658238443112" radius="0.8546907703575893"/>
			</geometry>
		</visual>
		<collision>
			<geometry>
				<cylinder length="1.6010658238443112" radius="0.8546907703575893"/>
			</geometry>
		</collision>
		<inertial>
			<mass value="3.6743209427316383"/>
			<inertia ixx="0.03" iyy="0.03" izz="0.03" ixy="0" ixz="0" iyz="0"/>
		</inertial>
	</link>
	<link name="752">
		<visual>
			<geometry>
				<cylinder length="1.6010658238443112" radius="0.8546907703575893"/>
			</geometry>
		</visual>
		<collision>
			<geometry>
				<cylinder length="1.6010658238443112" radius="0.8546907703575893"/>
			</geometry>
		</collision>
		<inertial>
			<mass value="3.6743209427316383"/>
			<inertia ixx="0.03" iyy="0.03" izz="0.03" ixy="0" ixz="0" iyz="0"/>
		</inertial>
	</link>
	<link name="753">
		<visual>
			<geometry>
				<cylinder length="1.6010658238443112" radius="0.8546907703575893"/>
			</geometry>
		</visual>
		<collision>
			<geometry>
				<cylinder length="1.6010658238443112" radius="0.8546907703575893"/>
			</geometry>
		</collision>
		<inertial>
			<mass value="3.6743209427316383"/>
			<inertia ixx="0.03" iyy="0.03" izz="0.03" ixy="0" ixz="0" iyz="0"/>
		</inertial>
	</link>
	<joint name="11_to_0" type="fixed">
		<parent link="0"/>
		<child link="11"/>
		<axis xyz="0 0 1"/>
		<limit effort="1" lower="0" upper="1" velocity="1"/>
		<origin xyz="0.7430241489714151 0.2539472840419892 0.2878001340490566" rpy="8.497723388301928 3.133278883442432 1.1492162219313824"/>
	</joint>
	<joint name="12_to_0" type="fixed">
		<parent link="0"/>
		<child link="12"/>
		<axis xyz="0 0 1"/>
		<limit effort="1" lower="0" upper="1" velocity="1"/>
		<origin xyz="0.7430241489714151 0.2539472840419892 0.2878001340490566" rpy="12.746585082452892 3.133278883442432 1.1492162219313824"/>
	</joint>
	<joint name="13_to_0" type="fixed">
		<parent link="0"/>
		<child link="13"/>
		<axis xyz="0 0 1"/>
		<limit effort="1" lower="0" upper="1" velocity="1"/>
		<origin xyz="0.7430241489714151 0.2539472840419892 0.2878001340490566" rpy="16.995446776603856 3.133278883442432 1.1492162219313824"/>
	</joint>
	<joint name="24_to_0" type="revolute">
		<parent link="0"/>
		<child link="24"/>
		<axis xyz="1 0 0"/>
		<limit effort="1" lower="0" upper="1" velocity="1"/>
		<origin xyz="0.9229388451517837 0.7538276987360758 0.4819215550848539" rpy="27.21844648809158 3.1339340395715243 3.996346079850344"/>
	</joint>
	<joint name="25_to_0" type="revolute">
		<parent link="0"/>
		<child link="25"/>
		<axis xyz="1 0 0"/>
		<limit effort="1" lower="0" upper="1" velocity="1"/>
		<origin xyz="0.9229388451517837 0.7538276987360758 0.4819215550848539" rpy="32.66213578570989 3.1339340395715243 3.996346079850344"/>
	</joint>
	<joint name="26_to_0" type="revolute">
		<parent link="0"/>
		<child link="26"/>
		<axis xyz="1 0 0"/>
		<limit effort="1" lower="0" upper="1" velocity="1"/>
		<origin xyz="0.9229388451517837 0.7538276987360758 0.4819215550848539" rpy="38.10582508332821 3.1339340395715243 3.996346079850344"/>
	</joint>
	<joint name="27_to_0" type="revolute">
		<parent link="0"/>
		<child link="27"/>
		<axis xyz="1 0 0"/>
		<limit effort="1" lower="0" upper="1" velocity="1"/>
		<origin xyz="0.9229388451517837 0.7538276987360758 0.4819215550848539" rpy="43.549514380946526 3.1339340395715243 3.996346079850344"/>
	</joint>
	<joint name="28_to_0" type="revolute">
		<parent link="0"/>
		<child link="28"/>
		<axis xyz="1 0 0"/>
		<limit effort="1" lower="0" upper="1" velocity="1"/>
		<origin xyz="0.9229388451517837 0.7538276987360758 0.4819215550848539" rpy="48.99320367856484 3.1339340395715243 3.996346079850344"/>
	</joint>
	<joint name="39_to_0" type="revolute">
		<parent link="0"/>
		<child link="39"/>
		<axis xyz="1 0 0"/>
		<limit effort="1" lower="0" upper="1" velocity="1"/>
		<origin xyz="0.9229388451517837 0.7538276987360758 0.4819215550848539" rpy="54.43689297618316 3.1339340395715243 4.553511212047006"/>
	</joint>
	<joint name="410_to_39" type="fixed">
		<parent link="39"/>
		<child link="410"/>
		<axis xyz="1 0 0"/>
		<limit effort="1" lower="0" upper="1" velocity="1"/>
		<origin xyz="0.12458435555841241 0.9747923794110072 0.1340527141682285" rpy="1.191988203362127 4.709952766991289 4.5314253203756065"/>
	</joint>
	<joint name="611_to_410" type="fixed">
		<parent link="410"/>
		<child link="611"/>
		<axis xyz="0 1 0"/>
		<limit effort="1" lower="0" upper="1" velocity="1"/>
		<origin xyz="0.629347726851477 0.8454548379917629 0.27970877604392375" rpy="12.52688145051932 4.922015672500073 0.5297269858768257"/>
	</joint>
	<joint name="412_to_39" type="fixed">
		<parent link="39"/>
		<child link="412"/>
		<axis xyz="1 0 0"/>
		<limit effort="1" lower="0" upper="1" velocity="1"/>
		<origin xyz="0.12458435555841241 0.9747923794110072 0.1340527141682285" rpy="1.7879823050431904 4.709952766991289 4.5314253203756065"/>
	</joint>
	<joint name="613_to_412" type="fixed">
		<parent link="412"/>
		<child link="613"/>
		<axis xyz="0 1 0"/>
		<limit effort="1" lower="0" upper="1" velocity="1"/>
		<origin xyz="0.629347726851477 0.8454548379917629 0.27970877604392375" rpy="12.52688145051932 4.922015672500073 0.5297269858768257"/>
	</joint>
	<joint name="514_to_39" type="fixed">
		<parent link="39"/>
		<child link="514"/>
		<axis xyz="0 1 0"/>
		<limit effort="1" lower="0" upper="1" velocity="1"/>
		<origin xyz="0.7246429657545651 1.0241146732799917 0.8353474872814421" rpy="20.15757989467255 3.8880320677405056 2.0414859598555237"/>
	</joint>
	<joint name="715_to_514" type="fixed">
		<parent link="514"/>
		<child link="715"/>
		<axis xyz="1 0 0"/>
		<limit effort="1" lower="0" upper="1" velocity="1"/>
		<origin xyz="0.9153089232349573 0.5680662717280514 0.9470977026213095" rpy="0.8509148225467349 3.5154074796115364 3.716105081425816"/>
	</joint>
	<joint name="716_to_514" type="fixed">
		<parent link="514"/>
		<child link="716"/>
		<axis xyz="1 0 0"/>
		<limit effort="1" lower="0" upper="1" velocity="1"/>
		<origin xyz="0.9153089232349573 0.5680662717280514 0.9470977026213095" rpy="1.2763722338201022 3.5154074796115364 3.716105081425816"/>
	</joint>
	<joint name="717_to_514" type="fixed">
		<parent link="514"/>
		<child link="717"/>
		<axis xyz="1 0 0"/>
		<limit effort="1" lower="0" upper="1" velocity="1"/>
		<origin xyz="0.9153089232349573 0.5680662717280514 0.9470977026213095" rpy="1.7018296450934698 3.5154074796115364 3.716105081425816"/>
	</joint>
	<joint name="718_to_514" type="fixed">
		<parent link="514"/>
		<child link="718"/>
		<axis xyz="1 0 0"/>
		<limit effort="1" lower="0" upper="1" velocity="1"/>
		<origin xyz="0.9153089232349573 0.5680662717280514 0.9470977026213095" rpy="2.1272870563668373 3.5154074796115364 3.716105081425816"/>
	</joint>
	<joint name="519_to_39" type="fixed">
		<parent link="39"/>
		<child link="519"/>
		<axis xyz="0 1 0"/>
		<limit effort="1" lower="0" upper="1" velocity="1"/>
		<origin xyz="0.7246429657545651 1.0241146732799917 0.8353474872814421" rpy="25.19697486834069 3.8880320677405056 2.0414859598555237"/>
	</joint>
	<joint name="720_to_519" type="fixed">
		<parent link="519"/>
		<child link="720"/>
		<axis xyz="1 0 0"/>
		<limit effort="1" lower="0" upper="1" velocity="1"/>
		<origin xyz="0.9153089232349573 0.5680662717280514 0.9470977026213095" rpy="0.8509148225467349 3.5154074796115364 3.716105081425816"/>
	</joint>
	<joint name="721_to_519" type="fixed">
		<parent link="519"/>
		<child link="721"/>
		<axis xyz="1 0 0"/>
		<limit effort="1" lower="0" upper="1" velocity="1"/>
		<origin xyz="0.9153089232349573 0.5680662717280514 0.9470977026213095" rpy="1.2763722338201022 3.5154074796115364 3.716105081425816"/>
	</joint>
	<joint name="722_to_519" type="fixed">
		<parent link="519"/>
		<child link="722"/>
		<axis xyz="1 0 0"/>
		<limit effort="1" lower="0" upper="1" velocity="1"/>
		<origin xyz="0.9153089232349573 0.5680662717280514 0.9470977026213095" rpy="1.7018296450934698 3.5154074796115364 3.716105081425816"/>
	</joint>
	<joint name="723_to_519" type="fixed">
		<parent link="519"/>
		<child link="723"/>
		<axis xyz="1 0 0"/>
		<limit effort="1" lower="0" upper="1" velocity="1"/>
		<origin xyz="0.9153089232349573 0.5680662717280514 0.9470977026213095" rpy="2.1272870563668373 3.5154074796115364 3.716105081425816"/>
	</joint>
	<joint name="324_to_0" type="revolute">
		<parent link="0"/>
		<child link="324"/>
		<axis xyz="1 0 0"/>
		<limit effort="1" lower="0" upper="1" velocity="1"/>
		<origin xyz="0.9229388451517837 0.7538276987360758 0.4819215550848539" rpy="59.88058227380147 3.1339340395715243 4.553511212047006"/>
	</joint>
	<joint name="425_to_324" type="fixed">
		<parent link="324"/>
		<child link="425"/>
		<axis xyz="1 0 0"/>
		<limit effort="1" lower="0" upper="1" velocity="1"/>
		<origin xyz="0.12458435555841241 0.9747923794110072 0.1340527141682285" rpy="1.191988203362127 4.709952766991289 4.5314253203756065"/>
	</joint>
	<joint name="626_to_425" type="fixed">
		<parent link="425"/>
		<child link="626"/>
		<axis xyz="0 1 0"/>
		<limit effort="1" lower="0" upper="1" velocity="1"/>
		<origin xyz="0.629347726851477 0.8454548379917629 0.27970877604392375" rpy="12.52688145051932 4.922015672500073 0.5297269858768257"/>
	</joint>
	<joint name="427_to_324" type="fixed">
		<parent link="324"/>
		<child link="427"/>
		<axis xyz="1 0 0"/>
		<limit effort="1" lower="0" upper="1" velocity="1"/>
		<origin xyz="0.12458435555841241 0.9747923794110072 0.1340527141682285" rpy="1.7879823050431904 4.709952766991289 4.5314253203756065"/>
	</joint>
	<joint name="628_to_427" type="fixed">
		<parent link="427"/>
		<child link="628"/>
		<axis xyz="0 1 0"/>
		<limit effort="1" lower="0" upper="1" velocity="1"/>
		<origin xyz="0.629347726851477 0.8454548379917629 0.27970877604392375" rpy="12.52688145051932 4.922015672500073 0.5297269858768257"/>
	</joint>
	<joint name="529_to_324" type="fixed">
		<parent link="324"/>
		<child link="529"/>
		<axis xyz="0 1 0"/>
		<limit effort="1" lower="0" upper="1" velocity="1"/>
		<origin xyz="0.7246429657545651 1.0241146732799917 0.8353474872814421" rpy="20.15757989467255 3.8880320677405056 2.0414859598555237"/>
	</joint>
	<joint name="730_to_529" type="fixed">
		<parent link="529"/>
		<child link="730"/>
		<axis xyz="1 0 0"/>
		<limit effort="1" lower="0" upper="1" velocity="1"/>
		<origin xyz="0.9153089232349573 0.5680662717280514 0.9470977026213095" rpy="0.8509148225467349 3.5154074796115364 3.716105081425816"/>
	</joint>
	<joint name="731_to_529" type="fixed">
		<parent link="529"/>
		<child link="731"/>
		<axis xyz="1 0 0"/>
		<limit effort="1" lower="0" upper="1" velocity="1"/>
		<origin xyz="0.9153089232349573 0.5680662717280514 0.9470977026213095" rpy="1.2763722338201022 3.5154074796115364 3.716105081425816"/>
	</joint>
	<joint name="732_to_529" type="fixed">
		<parent link="529"/>
		<child link="732"/>
		<axis xyz="1 0 0"/>
		<limit effort="1" lower="0" upper="1" velocity="1"/>
		<origin xyz="0.9153089232349573 0.5680662717280514 0.9470977026213095" rpy="1.7018296450934698 3.5154074796115364 3.716105081425816"/>
	</joint>
	<joint name="733_to_529" type="fixed">
		<parent link="529"/>
		<child link="733"/>
		<axis xyz="1 0 0"/>
		<limit effort="1" lower="0" upper="1" velocity="1"/>
		<origin xyz="0.9153089232349573 0.5680662717280514 0.9470977026213095" rpy="2.1272870563668373 3.5154074796115364 3.716105081425816"/>
	</joint>
	<joint name="534_to_324" type="fixed">
		<parent link="324"/>
		<child link="534"/>
		<axis xyz="0 1 0"/>
		<limit effort="1" lower="0" upper="1" velocity="1"/>
		<origin xyz="0.7246429657545651 1.0241146732799917 0.8353474872814421" rpy="25.19697486834069 3.8880320677405056 2.0414859598555237"/>
	</joint>
	<joint name="735_to_534" type="fixed">
		<parent link="534"/>
		<child link="735"/>
		<axis xyz="1 0 0"/>
		<limit effort="1" lower="0" upper="1" velocity="1"/>
		<origin xyz="0.9153089232349573 0.5680662717280514 0.9470977026213095" rpy="0.8509148225467349 3.5154074796115364 3.716105081425816"/>
	</joint>
	<joint name="736_to_534" type="fixed">
		<parent link="534"/>
		<child link="736"/>
		<axis xyz="1 0 0"/>
		<limit effort="1" lower="0" upper="1" velocity="1"/>
		<origin xyz="0.9153089232349573 0.5680662717280514 0.9470977026213095" rpy="1.2763722338201022 3.5154074796115364 3.716105081425816"/>
	</joint>
	<joint name="737_to_534" type="fixed">
		<parent link="534"/>
		<child link="737"/>
		<axis xyz="1 0 0"/>
		<limit effort="1" lower="0" upper="1" velocity="1"/>
		<origin xyz="0.9153089232349573 0.5680662717280514 0.9470977026213095" rpy="1.7018296450934698 3.5154074796115364 3.716105081425816"/>
	</joint>
	<joint name="738_to_534" type="fixed">
		<parent link="534"/>
		<child link="738"/>
		<axis xyz="1 0 0"/>
		<limit effort="1" lower="0" upper="1" velocity="1"/>
		<origin xyz="0.9153089232349573 0.5680662717280514 0.9470977026213095" rpy="2.1272870563668373 3.5154074796115364 3.716105081425816"/>
	</joint>
	<joint name="339_to_0" type="revolute">
		<parent link="0"/>
		<child link="339"/>
		<axis xyz="1 0 0"/>
		<limit effort="1" lower="0" upper="1" velocity="1"/>
		<origin xyz="0.9229388451517837 0.7538276987360758 0.4819215550848539" rpy="65.32427157141979 3.1339340395715243 4.553511212047006"/>
	</joint>
	<joint name="440_to_339" type="fixed">
		<parent link="339"/>
		<child link="440"/>
		<axis xyz="1 0 0"/>
		<limit effort="1" lower="0" upper="1" velocity="1"/>
		<origin xyz="0.12458435555841241 0.9747923794110072 0.1340527141682285" rpy="1.191988203362127 4.709952766991289 4.5314253203756065"/>
	</joint>
	<joint name="641_to_440" type="fixed">
		<parent link="440"/>
		<child link="641"/>
		<axis xyz="0 1 0"/>
		<limit effort="1" lower="0" upper="1" velocity="1"/>
		<origin xyz="0.629347726851477 0.8454548379917629 0.27970877604392375" rpy="12.52688145051932 4.922015672500073 0.5297269858768257"/>
	</joint>
	<joint name="442_to_339" type="fixed">
		<parent link="339"/>
		<child link="442"/>
		<axis xyz="1 0 0"/>
		<limit effort="1" lower="0" upper="1" velocity="1"/>
		<origin xyz="0.12458435555841241 0.9747923794110072 0.1340527141682285" rpy="1.7879823050431904 4.709952766991289 4.5314253203756065"/>
	</joint>
	<joint name="643_to_442" type="fixed">
		<parent link="442"/>
		<child link="643"/>
		<axis xyz="0 1 0"/>
		<limit effort="1" lower="0" upper="1" velocity="1"/>
		<origin xyz="0.629347726851477 0.8454548379917629 0.27970877604392375" rpy="12.52688145051932 4.922015672500073 0.5297269858768257"/>
	</joint>
	<joint name="544_to_339" type="fixed">
		<parent link="339"/>
		<child link="544"/>
		<axis xyz="0 1 0"/>
		<limit effort="1" lower="0" upper="1" velocity="1"/>
		<origin xyz="0.7246429657545651 1.0241146732799917 0.8353474872814421" rpy="20.15757989467255 3.8880320677405056 2.0414859598555237"/>
	</joint>
	<joint name="745_to_544" type="fixed">
		<parent link="544"/>
		<child link="745"/>
		<axis xyz="1 0 0"/>
		<limit effort="1" lower="0" upper="1" velocity="1"/>
		<origin xyz="0.9153089232349573 0.5680662717280514 0.9470977026213095" rpy="0.8509148225467349 3.5154074796115364 3.716105081425816"/>
	</joint>
	<joint name="746_to_544" type="fixed">
		<parent link="544"/>
		<child link="746"/>
		<axis xyz="1 0 0"/>
		<limit effort="1" lower="0" upper="1" velocity="1"/>
		<origin xyz="0.9153089232349573 0.5680662717280514 0.9470977026213095" rpy="1.2763722338201022 3.5154074796115364 3.716105081425816"/>
	</joint>
	<joint name="747_to_544" type="fixed">
		<parent link="544"/>
		<child link="747"/>
		<axis xyz="1 0 0"/>
		<limit effort="1" lower="0" upper="1" velocity="1"/>
		<origin xyz="0.9153089232349573 0.5680662717280514 0.9470977026213095" rpy="1.7018296450934698 3.5154074796115364 3.716105081425816"/>
	</joint>
	<joint name="748_to_544" type="fixed">
		<parent link="544"/>
		<child link="748"/>
		<axis xyz="1 0 0"/>
		<limit effort="1" lower="0" upper="1" velocity="1"/>
		<origin xyz="0.9153089232349573 0.5680662717280514 0.9470977026213095" rpy="2.1272870563668373 3.5154074796115364 3.716105081425816"/>
	</joint>
	<joint name="549_to_339" type="fixed">
		<parent link="339"/>
		<child link="549"/>
		<axis xyz="0 1 0"/>
		<limit effort="1" lower="0" upper="1" velocity="1"/>
		<origin xyz="0.7246429657545651 1.0241146732799917 0.8353474872814421" rpy="25.19697486834069 3.8880320677405056 2.0414859598555237"/>
	</joint>
	<joint name="750_to_549" type="fixed">
		<parent link="549"/>
		<child link="750"/>
		<axis xyz="1 0 0"/>
		<limit effort="1" lower="0" upper="1" velocity="1"/>
		<origin xyz="0.9153089232349573 0.5680662717280514 0.9470977026213095" rpy="0.8509148225467349 3.5154074796115364 3.716105081425816"/>
	</joint>
	<joint name="751_to_549" type="fixed">
		<parent link="549"/>
		<child link="751"/>
		<axis xyz="1 0 0"/>
		<limit effort="1" lower="0" upper="1" velocity="1"/>
		<origin xyz="0.9153089232349573 0.5680662717280514 0.9470977026213095" rpy="1.2763722338201022 3.5154074796115364 3.716105081425816"/>
	</joint>
	<joint name="752_to_549" type="fixed">
		<parent link="549"/>
		<child link="752"/>
		<axis xyz="1 0 0"/>
		<limit effort="1" lower="0" upper="1" velocity="1"/>
		<origin xyz="0.9153089232349573 0.5680662717280514 0.9470977026213095" rpy="1.7018296450934698 3.5154074796115364 3.716105081425816"/>
	</joint>
	<joint name="753_to_549" type="fixed">
		<parent link="549"/>
		<child link="753"/>
		<axis xyz="1 0 0"/>
		<limit effort="1" lower="0" upper="1" velocity="1"/>
		<origin xyz="0.9153089232349573 0.5680662717280514 0.9470977026213095" rpy="2.1272870563668373 3.5154074796115364 3.716105081425816"/>
	</joint>
</robot>
