<?xml version = "1.0"?>
<robot name="creature">
	<link name="0">
		<visual>
			<geometry>
				<cylinder length="0.7489213434340674" radius="0.4783686125905575"/>
			</geometry>
		</visual>
		<collision>
			<geometry>
				<cylinder length="0.7489213434340674" radius="0.4783686125905575"/>
			</geometry>
		</collision>
		<inertial>
			<mass value="0.5384079117474336"/>
			<inertia ixx="0.03" iyy="0.03" izz="0.03" ixy="0" ixz="0" iyz="0"/>
		</inertial>
	</link>
	<link name="11">
		<visual>
			<geometry>
				<cylinder length="0.5517421937512691" radius="0.27813277463346076"/>
			</geometry>
		</visual>
		<collision>
			<geometry>
				<cylinder length="0.5517421937512691" radius="0.27813277463346076"/>
			</geometry>
		</collision>
		<inertial>
			<mass value="0.1340881523871407"/>
			<inertia ixx="0.03" iyy="0.03" izz="0.03" ixy="0" ixz="0" iyz="0"/>
		</inertial>
	</link>
	<link name="22">
		<visual>
			<geometry>
				<cylinder length="0.23978755668681218" radius="0.9680864891969381"/>
			</geometry>
		</visual>
		<collision>
			<geometry>
				<cylinder length="0.23978755668681218" radius="0.9680864891969381"/>
			</geometry>
		</collision>
		<inertial>
			<mass value="0.7060002149890848"/>
			<inertia ixx="0.03" iyy="0.03" izz="0.03" ixy="0" ixz="0" iyz="0"/>
		</inertial>
	</link>
	<link name="23">
		<visual>
			<geometry>
				<cylinder length="0.23978755668681218" radius="0.9680864891969381"/>
			</geometry>
		</visual>
		<collision>
			<geometry>
				<cylinder length="0.23978755668681218" radius="0.9680864891969381"/>
			</geometry>
		</collision>
		<inertial>
			<mass value="0.7060002149890848"/>
			<inertia ixx="0.03" iyy="0.03" izz="0.03" ixy="0" ixz="0" iyz="0"/>
		</inertial>
	</link>
	<link name="24">
		<visual>
			<geometry>
				<cylinder length="0.23978755668681218" radius="0.9680864891969381"/>
			</geometry>
		</visual>
		<collision>
			<geometry>
				<cylinder length="0.23978755668681218" radius="0.9680864891969381"/>
			</geometry>
		</collision>
		<inertial>
			<mass value="0.7060002149890848"/>
			<inertia ixx="0.03" iyy="0.03" izz="0.03" ixy="0" ixz="0" iyz="0"/>
		</inertial>
	</link>
	<link name="25">
		<visual>
			<geometry>
				<cylinder length="0.23978755668681218" radius="0.9680864891969381"/>
			</geometry>
		</visual>
		<collision>
			<geometry>
				<cylinder length="0.23978755668681218" radius="0.9680864891969381"/>
			</geometry>
		</collision>
		<inertial>
			<mass value="0.7060002149890848"/>
			<inertia ixx="0.03" iyy="0.03" izz="0.03" ixy="0" ixz="0" iyz="0"/>
		</inertial>
	</link>
	<link name="26">
		<visual>
			<geometry>
				<cylinder length="0.23978755668681218" radius="0.9680864891969381"/>
			</geometry>
		</visual>
		<collision>
			<geometry>
				<cylinder length="0.23978755668681218" radius="0.9680864891969381"/>
			</geometry>
		</collision>
		<inertial>
			<mass value="0.7060002149890848"/>
			<inertia ixx="0.03" iyy="0.03" izz="0.03" ixy="0" ixz="0" iyz="0"/>
		</inertial>
	</link>
	<link name="27">
		<visual>
			<geometry>
				<cylinder length="0.23978755668681218" radius="0.9680864891969381"/>
			</geometry>
		</visual>
		<collision>
			<geometry>
				<cylinder length="0.23978755668681218" radius="0.9680864891969381"/>
			</geometry>
		</collision>
		<inertial>
			<mass value="0.7060002149890848"/>
			<inertia ixx="0.03" iyy="0.03" izz="0.03" ixy="0" ixz="0" iyz="0"/>
		</inertial>
	</link>
	<joint name="11_to_0" type="revolute">
		<parent link="0"/>
		<child link="11"/>
		<axis xyz="1 0 0"/>
		<limit effort="1" lower="0" upper="1" velocity="1"/>
		<origin xyz="0.043382377673685246 0.3859307244799799 1.0243279600540736" rpy="12.547678397386058 4.5506762365867495 0.4102607321800971"/>
	</joint>
	<joint name="22_to_11" type="fixed">
		<parent link="11"/>
		<child link="22"/>
		<axis xyz="1 0 0"/>
		<limit effort="1" lower="0" upper="1" velocity="1"/>
		<origin xyz="0.5462046862425327 0.06143571314039986 0.07519111216995389" rpy="7.540923214337221 1.3969197860385114 5.66348015169951"/>
	</joint>
	<joint name="23_to_11" type="fixed">
		<parent link="11"/>
		<child link="23"/>
		<axis xyz="1 0 0"/>
		<limit effort="1" lower="0" upper="1" velocity="1"/>
		<origin xyz="0.5462046862425327 0.06143571314039986 0.07519111216995389" rpy="11.311384821505833 1.3969197860385114 5.66348015169951"/>
	</joint>
	<joint name="24_to_11" type="fixed">
		<parent link="11"/>
		<child link="24"/>
		<axis xyz="1 0 0"/>
		<limit effort="1" lower="0" upper="1" velocity="1"/>
		<origin xyz="0.5462046862425327 0.06143571314039986 0.07519111216995389" rpy="15.081846428674442 1.3969197860385114 5.66348015169951"/>
	</joint>
	<joint name="25_to_11" type="fixed">
		<parent link="11"/>
		<child link="25"/>
		<axis xyz="1 0 0"/>
		<limit effort="1" lower="0" upper="1" velocity="1"/>
		<origin xyz="0.5462046862425327 0.06143571314039986 0.07519111216995389" rpy="18.852308035843052 1.3969197860385114 5.66348015169951"/>
	</joint>
	<joint name="26_to_11" type="fixed">
		<parent link="11"/>
		<child link="26"/>
		<axis xyz="1 0 0"/>
		<limit effort="1" lower="0" upper="1" velocity="1"/>
		<origin xyz="0.5462046862425327 0.06143571314039986 0.07519111216995389" rpy="22.622769643011665 1.3969197860385114 5.66348015169951"/>
	</joint>
	<joint name="27_to_11" type="fixed">
		<parent link="11"/>
		<child link="27"/>
		<axis xyz="1 0 0"/>
		<limit effort="1" lower="0" upper="1" velocity="1"/>
		<origin xyz="0.5462046862425327 0.06143571314039986 0.07519111216995389" rpy="26.393231250180275 1.3969197860385114 5.66348015169951"/>
	</joint>
</robot>
